<?xml version="1.0" ?>
<!-- =================================================================================== -->
<!-- |    This document was autogenerated by xacro from d:/Leon/Python/rbs_working/iiwa_description/urdf/iiwa14.urdf.xacro | -->
<!-- |    EDITING THIS FILE BY HAND IS NOT RECOMMENDED                                 | -->
<!-- =================================================================================== -->
<robot xmlns:xacro="http://www.ros.org/wiki/xacro" name="iiwa14">
  <!-- Import Rviz colors -->
  <material name="Black">
    <color rgba="0.0 0.0 0.0 1.0"/>
  </material>
  <material name="Blue">
    <color rgba="0.0 0.0 0.8 1.0"/>
  </material>
  <material name="Green">
    <color rgba="0.0 0.8 0.0 1.0"/>
  </material>
  <material name="Grey">
    <color rgba="0.6 0.6 0.6 1.0"/>
  </material>
  <material name="Orange">
    <color rgba="1.0 0.4235294117647059 0.0392156862745098 1.0"/>
  </material>
  <material name="Brown">
    <color rgba="0.8705882352941177 0.8117647058823529 0.7647058823529411 1.0"/>
  </material>
  <material name="Red">
    <color rgba="0.8 0.0 0.0 1.0"/>
  </material>
  <material name="White">
    <color rgba="1.0 1.0 1.0 1.0"/>
  </material>
  <material name="Silver">
    <color rgba="0.8 0.8 0.8 1.0"/>
  </material>
  <!--Import the lbr iiwa macro -->
  <xacro:arg name="hardware_interface" default="PositionJointInterface"/>
  <xacro:arg name="robot_name" default="iiwa"/>
  <!-- Fix to world just for testing -->
  <link name="world"/>
  <!--iiwa-->
  <joint name="world_iiwa_joint" type="fixed">
    <origin xyz="0 0 0.0" rpy="0 0 0"/>
    <parent link="world"/>
    <child link="iiwa_link_0"/>
  </joint>
  <link name="iiwa_link_0">
    <inertial>
      <origin xyz="-0.1 0 0.07" rpy="0 0 0"/>
      <mass value="5"/>
      <inertia ixx="0.05" ixy="0" ixz="0" iyy="0.06" iyz="0" izz="0.03"/>
    </inertial>
    <visual>
      <origin xyz="0 0 0" rpy="0 0 0"/>
      <geometry>
        <mesh filename="package://iiwa14/meshes/visual/link_0.obj"/>
      </geometry>
      <material name="Grey"/>
    </visual>
    <collision>
      <origin xyz="0 0 0" rpy="0 0 0"/>
      <geometry>
        <mesh filename="package://iiwa14/meshes/collision/link_0_s.stl"/>
      </geometry>
      <material name="Grey"/>
    </collision>
    <self_collision_checking>
      <origin xyz="0 0 0" rpy="0 0 0"/>
      <geometry>
        <capsule radius="0.15" length="0.25"/>
      </geometry>
    </self_collision_checking>
  </link>
  <joint name="iiwa_joint_1" type="revolute">
    <parent link="iiwa_link_0"/>
    <child link="iiwa_link_1"/>
    <origin xyz="0 0 0.1575" rpy="0 0 0"/>
    <axis xyz="0 0 1"/>
    <limit lower="-2.9670597283903604" upper="2.9670597283903604" effort="300" velocity="10"/>
    <safety_controller soft_lower_limit="-2.9321531433504737" soft_upper_limit="2.9321531433504737" k_position="100" k_velocity="2"/>
    <dynamics damping="0.0" friction="0.0"/>
  </joint>
  <link name="iiwa_link_1">
    <inertial>
      <origin xyz="0 -0.03 0.12" rpy="0 0 0"/>
      <mass value="4"/>
      <inertia ixx="0.1" ixy="0" ixz="0" iyy="0.09" iyz="0" izz="0.02"/>
    </inertial>
    <visual>
      <origin xyz="0 0 0" rpy="0 0 0"/>
      <geometry>
        <mesh filename="package://iiwa14/meshes/visual/link_1.obj"/>
      </geometry>
      <material name="Grey"/>
    </visual>
    <collision>
      <origin xyz="0 0 0" rpy="0 0 0"/>
      <geometry>
        <mesh filename="package://iiwa14/meshes/collision/link_1_s.stl"/>
      </geometry>
      <material name="Orange"/>
    </collision>
  </link>
  <joint name="iiwa_joint_2" type="revolute">
    <parent link="iiwa_link_1"/>
    <child link="iiwa_link_2"/>
    <origin xyz="0 0 0.2025" rpy="1.5707963267948966   0 3.141592653589793"/>
    <axis xyz="0 0 1"/>
    <limit lower="-2.0943951023931953" upper="2.0943951023931953" effort="300" velocity="10"/>
    <safety_controller soft_lower_limit="-2.0594885173533086" soft_upper_limit="2.0594885173533086" k_position="100" k_velocity="2"/>
    <dynamics damping="0.0" friction="0.0"/>
  </joint>
  <link name="iiwa_link_2">
    <inertial>
      <origin xyz="0.0003 0.059 0.042" rpy="0 0 0"/>
      <mass value="4"/>
      <inertia ixx="0.05" ixy="0" ixz="0" iyy="0.018" iyz="0" izz="0.044"/>
    </inertial>
    <visual>
      <origin xyz="0 0 0" rpy="0 0 0"/>
      <geometry>
        <mesh filename="package://iiwa14/meshes/visual/link_2_orange.obj"/>
      </geometry>
      <material name="Orange"/>
    </visual>
    <visual>
      <origin xyz="0 0 0" rpy="0 0 0"/>
      <geometry>
        <mesh filename="package://iiwa14/meshes/visual/link_2_grey.obj"/>
      </geometry>
      <material name="Grey"/>
    </visual>
    <collision>
      <origin xyz="0 0 0" rpy="0 0 0"/>
      <geometry>
        <mesh filename="package://iiwa14/meshes/collision/link_2_s.stl"/>
      </geometry>
      <material name="Orange"/>
    </collision>
  </link>
  <joint name="iiwa_joint_3" type="revolute">
    <parent link="iiwa_link_2"/>
    <child link="iiwa_link_3"/>
    <origin xyz="0 0.2045 0" rpy="1.5707963267948966 0 3.141592653589793"/>
    <axis xyz="0 0 1"/>
    <limit lower="-2.9670597283903604" upper="2.9670597283903604" effort="300" velocity="10"/>
    <safety_controller soft_lower_limit="-2.9321531433504737" soft_upper_limit="2.9321531433504737" k_position="100" k_velocity="2"/>
    <dynamics damping="0.0" friction="0.0"/>
  </joint>
  <link name="iiwa_link_3">
    <inertial>
      <origin xyz="0 0.03 0.13" rpy="0 0 0"/>
      <mass value="3"/>
      <inertia ixx="0.08" ixy="0" ixz="0" iyy="0.075" iyz="0" izz="0.01"/>
    </inertial>
    <visual>
      <origin xyz="0 0 0" rpy="0 0 0"/>
      <geometry>
        <mesh filename="package://iiwa14/meshes/visual/link_3.obj"/>
      </geometry>
      <material name="Grey"/>
    </visual>
    <visual>
      <origin xyz="0 0 0" rpy="0 0 0"/>
      <geometry>
        <mesh filename="package://iiwa14/meshes/visual/band.obj"/>
      </geometry>
      <material name="Silver"/>
    </visual>
    <visual>
      <origin xyz="0 0 0" rpy="0 0 0"/>
      <geometry>
        <mesh filename="package://iiwa14/meshes/visual/kuka.obj"/>
      </geometry>
      <material name="Black"/>
    </visual>
    <collision>
      <origin xyz="0 0 0" rpy="0 0 0"/>
      <geometry>
        <mesh filename="package://iiwa14/meshes/collision/link_3_s.stl"/>
      </geometry>
      <material name="Orange"/>
    </collision>
  </link>
  <joint name="iiwa_joint_4" type="revolute">
    <parent link="iiwa_link_3"/>
    <child link="iiwa_link_4"/>
    <origin xyz="0 0 0.2155" rpy="1.5707963267948966 0 0"/>
    <axis xyz="0 0 1"/>
    <limit lower="-2.0943951023931953" upper="2.0943951023931953" effort="300" velocity="10"/>
    <safety_controller soft_lower_limit="-2.0594885173533086" soft_upper_limit="2.0594885173533086" k_position="100" k_velocity="2"/>
    <dynamics damping="0.0" friction="0.0"/>
  </joint>
  <link name="iiwa_link_4">
    <inertial>
      <origin xyz="0 0.067 0.034" rpy="0 0 0"/>
      <mass value="2.7"/>
      <inertia ixx="0.03" ixy="0" ixz="0" iyy="0.01" iyz="0" izz="0.029"/>
    </inertial>
    <visual>
      <origin xyz="0 0 0" rpy="0 0 0"/>
      <geometry>
        <mesh filename="package://iiwa14/meshes/visual/link_4_orange.obj"/>
      </geometry>
      <material name="Orange"/>
    </visual>
    <visual>
      <origin xyz="0 0 0" rpy="0 0 0"/>
      <geometry>
        <mesh filename="package://iiwa14/meshes/visual/link_4_grey.obj"/>
      </geometry>
      <material name="Grey"/>
    </visual>
    <collision>
      <origin xyz="0 0 0" rpy="0 0 0"/>
      <geometry>
        <mesh filename="package://iiwa14/meshes/collision/link_4_s.stl"/>
      </geometry>
      <material name="Orange"/>
    </collision>
  </link>
  <joint name="iiwa_joint_5" type="revolute">
    <parent link="iiwa_link_4"/>
    <child link="iiwa_link_5"/>
    <origin xyz="0 0.1845 0" rpy="-1.5707963267948966 3.141592653589793 0"/>
    <axis xyz="0 0 1"/>
    <limit lower="-2.9670597283903604" upper="2.9670597283903604" effort="300" velocity="10"/>
    <safety_controller soft_lower_limit="-2.9321531433504737" soft_upper_limit="2.9321531433504737" k_position="100" k_velocity="2"/>
    <dynamics damping="0.0" friction="0.0"/>
  </joint>
  <link name="iiwa_link_5">
    <inertial>
      <origin xyz="0.0001 0.021 0.076" rpy="0 0 0"/>
      <mass value="1.7"/>
      <inertia ixx="0.02" ixy="0" ixz="0" iyy="0.018" iyz="0" izz="0.005"/>
    </inertial>
    <visual>
      <origin xyz="0 0 0" rpy="0 0 0"/>
      <geometry>
        <mesh filename="package://iiwa14/meshes/visual/link_5.obj"/>
      </geometry>
      <material name="Grey"/>
    </visual>
    <visual>
      <origin xyz="0 0 0" rpy="0 0 0"/>
      <geometry>
        <mesh filename="package://iiwa14/meshes/visual/band.obj"/>
      </geometry>
      <material name="Silver"/>
    </visual>
    <visual>
      <origin xyz="0 0 0" rpy="0 0 0"/>
      <geometry>
        <mesh filename="package://iiwa14/meshes/visual/kuka.obj"/>
      </geometry>
      <material name="Black"/>
    </visual>
    <collision>
      <origin xyz="0 0 0" rpy="0 0 0"/>
      <geometry>
        <mesh filename="package://iiwa14/meshes/collision/link_5_s.stl"/>
      </geometry>
      <material name="Orange"/>
    </collision>
  </link>
  <joint name="iiwa_joint_6" type="revolute">
    <parent link="iiwa_link_5"/>
    <child link="iiwa_link_6"/>
    <origin xyz="0 0 0.2155" rpy="1.5707963267948966 0 0"/>
    <axis xyz="0 0 1"/>
    <limit lower="-2.0943951023931953" upper="2.0943951023931953" effort="300" velocity="10"/>
    <safety_controller soft_lower_limit="-2.0594885173533086" soft_upper_limit="2.0594885173533086" k_position="100" k_velocity="2"/>
    <dynamics damping="0.0" friction="0.0"/>
  </joint>
  <link name="iiwa_link_6">
    <inertial>
      <origin xyz="0 0.0006 0.0004" rpy="0 0 0"/>
      <mass value="1.8"/>
      <inertia ixx="0.025" ixy="0" ixz="0" iyy="0.0136" iyz="0" izz="0.0247"/>
    </inertial>
    <visual>
      <origin xyz="0 0 0" rpy="0 0 0"/>
      <geometry>
        <mesh filename="package://iiwa14/meshes/visual/link_6_orange.obj"/>
      </geometry>
      <material name="Orange"/>
    </visual>
    <visual>
      <origin xyz="0 0 0" rpy="0 0 0"/>
      <geometry>
        <mesh filename="package://iiwa14/meshes/visual/link_6_grey.obj"/>
      </geometry>
      <material name="Grey"/>
    </visual>
    <collision>
      <origin xyz="0 0 0" rpy="0 0 0"/>
      <geometry>
        <mesh filename="package://iiwa14/meshes/collision/link_6_s.stl"/>
      </geometry>
      <material name="Orange"/>
    </collision>
  </link>
  <joint name="iiwa_joint_7" type="revolute">
    <parent link="iiwa_link_6"/>
    <child link="iiwa_link_7"/>
    <origin xyz="0 0.081 0" rpy="-1.5707963267948966 3.141592653589793 0"/>
    <axis xyz="0 0 1"/>
    <limit lower="-3.0543261909900763" upper="3.0543261909900763" effort="300" velocity="10"/>
    <safety_controller soft_lower_limit="-3.01941960595019" soft_upper_limit="3.01941960595019" k_position="100" k_velocity="2"/>
    <dynamics damping="0.0" friction="0.0"/>
  </joint>
  <link name="iiwa_link_7">
    <inertial>
      <origin xyz="0 0 0.02" rpy="0 0 0"/>
      <mass value="0.3"/>
      <inertia ixx="0.001" ixy="0" ixz="0" iyy="0.001" iyz="0" izz="0.001"/>
    </inertial>
    <visual>
      <origin xyz="0 0 0" rpy="0 0 0"/>
      <geometry>
        <!--           <mesh filename="package://iiwa14/meshes/visual/link_7.obj"/> -->
        <mesh filename="package://iiwa14/meshes/visual/link_7-MF-Touch-pneumatisch.stl"/>
      </geometry>
      <material name="Grey"/>
    </visual>
    <collision>
      <origin xyz="0 0 0" rpy="0 0 0"/>
      <geometry>
        <!--           <mesh filename="package://iiwa14/meshes/collision/link_7_s.stl"/> -->
        <mesh filename="package://iiwa14/meshes/collision/link_7-MF-Touch-pneumatisch_s.stl"/>
      </geometry>
      <material name="Grey"/>
    </collision>
  </link>
  <joint name="iiwa_joint_ee" type="fixed">
    <parent link="iiwa_link_7"/>
    <child link="iiwa_link_ee"/>
    <origin xyz="0 0 0.045" rpy="0 -1.5707963267948966 0"/>
  </joint>
  <link name="iiwa_link_ee">
    </link>
  <joint name="iiwa_joint_ee_kuka" type="fixed">
    <parent link="iiwa_link_7"/>
    <child link="iiwa_link_ee_kuka"/>
    <origin xyz="0 0 0.045" rpy="3.141592653589793 3.141592653589793 3.141592653589793"/>
    <axis xyz="0 0 1"/>
  </joint>
  <joint name="iiwa_joint_ee_kuka_mft_pneum" type="fixed">
    <parent link="iiwa_link_7"/>
    <child link="iiwa_link_ee_kuka_mft_pneum"/>
    <origin xyz="0 0 0.071" rpy="0 -1.5707963267948966 0"/>
  </joint>
  <link name="iiwa_link_ee_kuka">
    </link>
  <link name="iiwa_link_ee_kuka_mft_pneum">
    </link>
  <gazebo reference="iiwa_link_0">
    <material>Gazebo/Grey</material>
    <mu1>0.2</mu1>
    <mu2>0.2</mu2>
  </gazebo>
  <gazebo reference="iiwa_link_1">
    <material>Gazebo/Orange</material>
    <mu1>0.2</mu1>
    <mu2>0.2</mu2>
  </gazebo>
  <gazebo reference="iiwa_link_2">
    <material>Gazebo/Orange</material>
    <mu1>0.2</mu1>
    <mu2>0.2</mu2>
  </gazebo>
  <gazebo reference="iiwa_link_3">
    <material>Gazebo/Orange</material>
    <mu1>0.2</mu1>
    <mu2>0.2</mu2>
  </gazebo>
  <gazebo reference="iiwa_link_4">
    <material>Gazebo/Orange</material>
    <mu1>0.2</mu1>
    <mu2>0.2</mu2>
  </gazebo>
  <gazebo reference="iiwa_link_5">
    <material>Gazebo/Orange</material>
    <mu1>0.2</mu1>
    <mu2>0.2</mu2>
  </gazebo>
  <gazebo reference="iiwa_link_6">
    <material>Gazebo/Orange</material>
    <mu1>0.2</mu1>
    <mu2>0.2</mu2>
  </gazebo>
  <gazebo reference="iiwa_link_7">
    <material>Gazebo/Grey</material>
    <mu1>0.2</mu1>
    <mu2>0.2</mu2>
  </gazebo>
  <transmission name="iiwa_tran_1">
    <robotNamespace>/iiwa</robotNamespace>
    <type>transmission_interface/SimpleTransmission</type>
    <joint name="iiwa_joint_1">
      <hardwareInterface>D:\Leon\Python\rbs_working/hardware_interface</hardwareInterface>
    </joint>
    <actuator name="iiwa_motor_1">
      <hardwareInterface>D:\Leon\Python\rbs_working/hardware_interface</hardwareInterface>
      <mechanicalReduction>1</mechanicalReduction>
    </actuator>
  </transmission>
  <transmission name="iiwa_tran_2">
    <robotNamespace>/iiwa</robotNamespace>
    <type>transmission_interface/SimpleTransmission</type>
    <joint name="iiwa_joint_2">
      <hardwareInterface>D:\Leon\Python\rbs_working/hardware_interface</hardwareInterface>
    </joint>
    <actuator name="iiwa_motor_2">
      <hardwareInterface>D:\Leon\Python\rbs_working/hardware_interface</hardwareInterface>
      <mechanicalReduction>1</mechanicalReduction>
    </actuator>
  </transmission>
  <transmission name="iiwa_tran_3">
    <robotNamespace>/iiwa</robotNamespace>
    <type>transmission_interface/SimpleTransmission</type>
    <joint name="iiwa_joint_3">
      <hardwareInterface>D:\Leon\Python\rbs_working/hardware_interface</hardwareInterface>
    </joint>
    <actuator name="iiwa_motor_3">
      <hardwareInterface>D:\Leon\Python\rbs_working/hardware_interface</hardwareInterface>
      <mechanicalReduction>1</mechanicalReduction>
    </actuator>
  </transmission>
  <transmission name="iiwa_tran_4">
    <robotNamespace>/iiwa</robotNamespace>
    <type>transmission_interface/SimpleTransmission</type>
    <joint name="iiwa_joint_4">
      <hardwareInterface>D:\Leon\Python\rbs_working/hardware_interface</hardwareInterface>
    </joint>
    <actuator name="iiwa_motor_4">
      <hardwareInterface>D:\Leon\Python\rbs_working/hardware_interface</hardwareInterface>
      <mechanicalReduction>1</mechanicalReduction>
    </actuator>
  </transmission>
  <transmission name="iiwa_tran_5">
    <robotNamespace>/iiwa</robotNamespace>
    <type>transmission_interface/SimpleTransmission</type>
    <joint name="iiwa_joint_5">
      <hardwareInterface>D:\Leon\Python\rbs_working/hardware_interface</hardwareInterface>
    </joint>
    <actuator name="iiwa_motor_5">
      <hardwareInterface>D:\Leon\Python\rbs_working/hardware_interface</hardwareInterface>
      <mechanicalReduction>1</mechanicalReduction>
    </actuator>
  </transmission>
  <transmission name="iiwa_tran_6">
    <robotNamespace>/iiwa</robotNamespace>
    <type>transmission_interface/SimpleTransmission</type>
    <joint name="iiwa_joint_6">
      <hardwareInterface>D:\Leon\Python\rbs_working/hardware_interface</hardwareInterface>
    </joint>
    <actuator name="iiwa_motor_6">
      <hardwareInterface>D:\Leon\Python\rbs_working/hardware_interface</hardwareInterface>
      <mechanicalReduction>1</mechanicalReduction>
    </actuator>
  </transmission>
  <transmission name="iiwa_tran_7">
    <robotNamespace>/iiwa</robotNamespace>
    <type>transmission_interface/SimpleTransmission</type>
    <joint name="iiwa_joint_7">
      <hardwareInterface>D:\Leon\Python\rbs_working/hardware_interface</hardwareInterface>
    </joint>
    <actuator name="iiwa_motor_7">
      <hardwareInterface>D:\Leon\Python\rbs_working/hardware_interface</hardwareInterface>
      <mechanicalReduction>1</mechanicalReduction>
    </actuator>
  </transmission>
</robot>
