<!-- ======================================================
	MuJoCo model
	
	Model   : KUKA LBR iiwa 14 scene
	Author  : Leon Zlajpah

	Copyright 2025 IJS 

====================================================== -->
<mujoco model="iiwa14_scene">
  <compiler angle="radian" meshdir="assets/"/>

  <option timestep="0.001" integrator="implicitfast"/>

  <size nkey="1"/>

  <visual>
    <map stiffness="700" fogstart="1" fogend="15" zfar="40" haze="1" shadowscale="0.5"/>
    <rgba haze="0.15 0.25 0.35 1"/>
  </visual>

  <statistic meansize="0.05"/>

  <default>
    <light castshadow="false"/>
    <general biastype="affine" biasprm="0 -1"/>
    <default class="iiwa14_main">
      <light castshadow="true"/>
      <general biastype="none" biasprm="0 0"/>
      <default class="iiwa14_robot">
        <material shininess="0.25"/>
        <site size="0.001 0.005 0.005" group="4" rgba="1 0 0 1"/>
        <general biastype="affine" gainprm="2000" biasprm="0 -2000 -200"/>
        <default class="iiwa14_joint1">
          <joint range="-2.96706 2.96706"/>
          <general ctrlrange="-2.96706 2.96706"/>
          <default class="iiwa14_joint2">
            <joint range="-2.0944 2.0944"/>
            <general ctrlrange="-2.0944 2.0944"/>
          </default>
        </default>
        <default class="iiwa14_joint3">
          <joint range="-3.05433 3.05433"/>
          <general ctrlrange="-3.05433 3.05433"/>
        </default>
        <default class="iiwa14_visual">
          <geom type="mesh" contype="0" conaffinity="0" group="2" material="gray"/>
        </default>
        <default class="iiwa14_collision">
          <geom group="3"/>
        </default>
      </default>
    </default>
  </default>

  <asset>
    <texture type="skybox" colorspace="auto" builtin="gradient" rgb1="0.3 0.5 0.7" rgb2="0 0 0" width="512" height="3072"/>
    <texture type="2d" colorspace="auto" name="texplane" builtin="checker" mark="cross" rgb1="0.2 0.3 0.4" rgb2="0.1 0.15 0.2" markrgb="0.8 0.8 0.8" width="512" height="512"/>
    <material name="matplane" texture="texplane" texuniform="true" texrepeat="10 10" reflectance="0.3"/>
    <material name="iiwa14_gray" class="iiwa14_robot" rgba="0.4 0.4 0.4 1"/>
    <material name="iiwa14_light_gray" class="iiwa14_robot" rgba="0.6 0.6 0.6 1"/>
    <material name="iiwa14_black" class="iiwa14_robot" rgba="0 0 0 1"/>
    <material name="iiwa14_orange" class="iiwa14_robot" rgba="1 0.423529 0.0392157 1"/>
    <mesh name="iiwa14_link_0" content_type="model/obj" file="iiwa14/link_0.obj"/>
    <mesh name="iiwa14_link_1" content_type="model/obj" file="iiwa14/link_1.obj"/>
    <mesh name="iiwa14_link_2_orange" content_type="model/obj" file="iiwa14/link_2_orange.obj"/>
    <mesh name="iiwa14_link_2_grey" content_type="model/obj" file="iiwa14/link_2_grey.obj"/>
    <mesh name="iiwa14_link_3" content_type="model/obj" file="iiwa14/link_3.obj"/>
    <mesh name="iiwa14_band" content_type="model/obj" file="iiwa14/band.obj"/>
    <mesh name="iiwa14_kuka" content_type="model/obj" file="iiwa14/kuka.obj"/>
    <mesh name="iiwa14_link_4_orange" content_type="model/obj" file="iiwa14/link_4_orange.obj"/>
    <mesh name="iiwa14_link_4_grey" content_type="model/obj" file="iiwa14/link_4_grey.obj"/>
    <mesh name="iiwa14_link_5" content_type="model/obj" file="iiwa14/link_5.obj"/>
    <mesh name="iiwa14_link_6_orange" content_type="model/obj" file="iiwa14/link_6_orange.obj"/>
    <mesh name="iiwa14_link_6_grey" content_type="model/obj" file="iiwa14/link_6_grey.obj"/>
    <mesh name="iiwa14_link_7" content_type="model/obj" file="iiwa14/link_7.obj"/>
  </asset>

  <worldbody>
    <geom name="ground" size="0 0 1" type="plane" condim="1" material="matplane"/>
    <site pos="0.5 0 0" quat="0.707107 0 0.707107 0" size="0.005 0.5" type="cylinder" rgba="1 0 0 1"/>
    <site pos="0 0.5 0" quat="0.707107 0.707107 0 0" size="0.005 0.5" type="cylinder" rgba="0 1 0 1"/>
    <site pos="0 0 0.5" size="0.005 0.5" type="cylinder" rgba="0 0 1 1"/>
    <light pos="0 0 2" dir="0 0 -1" diffuse="0.4 0.4 0.4" specular="0.1 0.1 0.1"/>
    <light pos="0 0 4" dir="0 0 -1" type="directional" diffuse="0.8 0.8 0.8" specular="0.2 0.2 0.2"/>
    <body name="iiwa14" childclass="iiwa14_robot">
      <site name="iiwa14_x" pos="0.25 0 0" quat="0.707107 0 0.707107 0" size="0.01 0.25" group="1" type="cylinder"/>
      <site name="iiwa14_y" pos="0 0.25 0" quat="0.707107 0.707107 0 0" size="0.01 0.25" group="1" type="cylinder" rgba="0 1 0 1"/>
      <site name="iiwa14_z" pos="0 0 0.25" size="0.01 0.25" group="1" type="cylinder" rgba="0 0 1 1"/>
      <body name="iiwa14_link0">
        <inertial pos="-0.1 0 0.07" mass="5" diaginertia="0.05 0.06 0.03"/>
        <geom class="iiwa14_visual" material="iiwa14_gray" mesh="iiwa14_link_0"/>
        <geom class="iiwa14_collision" size="0.12" pos="0 0 0.03"/>
        <geom class="iiwa14_collision" size="0.08" pos="-0.08 0 0.103"/>
        <geom class="iiwa14_collision" size="0.08" pos="-0.08 0 0.04"/>
        <geom class="iiwa14_collision" size="0.1" pos="0 0 0.14"/>
        <body name="iiwa14_link1" pos="0 0 0.1575">
          <inertial pos="0 -0.03 0.12" mass="5.76" diaginertia="0.0333 0.033 0.0123"/>
          <joint name="iiwa14_joint1" class="iiwa14_joint1" pos="0 0 0" axis="0 0 1"/>
          <geom class="iiwa14_visual" material="iiwa14_gray" mesh="iiwa14_link_1"/>
          <geom class="iiwa14_collision" size="0.08" pos="0 0 -0.0005"/>
          <geom class="iiwa14_collision" size="0.075" pos="0.01 -0.025 0.0425"/>
          <geom class="iiwa14_collision" size="0.075" pos="-0.01 -0.025 0.0425"/>
          <geom class="iiwa14_collision" size="0.07" pos="0.01 -0.045 0.1025"/>
          <geom class="iiwa14_collision" size="0.07" pos="-0.01 -0.045 0.1025"/>
          <body name="iiwa14_link2" pos="0 0 0.2025" quat="0 0 0.707107 0.707107">
            <inertial pos="0.0003 0.059 0.042" quat="0 0 0.707107 0.707107" mass="6.35" diaginertia="0.0305 0.0304 0.011"/>
            <joint name="iiwa14_joint2" class="iiwa14_joint2" pos="0 0 0" axis="0 0 1"/>
            <geom class="iiwa14_visual" material="iiwa14_orange" mesh="iiwa14_link_2_orange"/>
            <geom class="iiwa14_visual" material="iiwa14_gray" mesh="iiwa14_link_2_grey"/>
            <geom class="iiwa14_collision" size="0.095" pos="0 0 -0.01"/>
            <geom class="iiwa14_collision" size="0.09" pos="0 0 0.045"/>
            <geom class="iiwa14_collision" size="0.07" pos="-0.01 0.04 0.054"/>
            <geom class="iiwa14_collision" size="0.065" pos="-0.01 0.09 0.04"/>
            <geom class="iiwa14_collision" size="0.065" pos="-0.01 0.13 0.02"/>
            <geom class="iiwa14_collision" size="0.07" pos="0.01 0.04 0.054"/>
            <geom class="iiwa14_collision" size="0.065" pos="0.01 0.09 0.04"/>
            <geom class="iiwa14_collision" size="0.065" pos="0.01 0.13 0.02"/>
            <geom class="iiwa14_collision" size="0.075" pos="0 0.18 0"/>
            <body name="iiwa14_link3" pos="0 0.2045 0" quat="0 0 0.707107 0.707107">
              <inertial pos="0 0.03 0.13" mass="3.5" diaginertia="0.025 0.0238 0.0076"/>
              <joint name="iiwa14_joint3" class="iiwa14_joint1" pos="0 0 0" axis="0 0 1"/>
              <geom class="iiwa14_visual" material="iiwa14_gray" mesh="iiwa14_link_3"/>
              <geom class="iiwa14_visual" material="iiwa14_light_gray" mesh="iiwa14_band"/>
              <geom class="iiwa14_visual" material="iiwa14_black" mesh="iiwa14_kuka"/>
              <geom class="iiwa14_collision" size="0.075" pos="0 0 0.0355"/>
              <geom class="iiwa14_collision" size="0.06" pos="0.01 0.023 0.0855"/>
              <geom class="iiwa14_collision" size="0.055" pos="0.01 0.048 0.1255"/>
              <geom class="iiwa14_collision" size="0.06" pos="0.01 0.056 0.1755"/>
              <geom class="iiwa14_collision" size="0.06" pos="-0.01 0.023 0.0855"/>
              <geom class="iiwa14_collision" size="0.055" pos="-0.01 0.048 0.1255"/>
              <geom class="iiwa14_collision" size="0.06" pos="-0.01 0.056 0.1755"/>
              <geom class="iiwa14_collision" size="0.075" pos="0 0.045 0.2155"/>
              <geom class="iiwa14_collision" size="0.075" pos="0 0 0.2155"/>
              <body name="iiwa14_link4" pos="0 0 0.2155" quat="0.707107 0.707107 0 0">
                <inertial pos="0 0.067 0.034" quat="0.707107 0.707107 0 0" mass="3.5" diaginertia="0.017 0.0164 0.006"/>
                <joint name="iiwa14_joint4" class="iiwa14_joint2" pos="0 0 0" axis="0 0 1"/>
                <geom class="iiwa14_visual" material="iiwa14_orange" mesh="iiwa14_link_4_orange"/>
                <geom class="iiwa14_visual" material="iiwa14_gray" mesh="iiwa14_link_4_grey"/>
                <geom class="iiwa14_collision" size="0.078" pos="0 0.01 0.046"/>
                <geom class="iiwa14_collision" size="0.06" pos="0.01 0.06 0.052"/>
                <geom class="iiwa14_collision" size="0.065" pos="0.01 0.12 0.034"/>
                <geom class="iiwa14_collision" size="0.06" pos="-0.01 0.06 0.052"/>
                <geom class="iiwa14_collision" size="0.065" pos="-0.01 0.12 0.034"/>
                <geom class="iiwa14_collision" size="0.075" pos="0 0.184 0"/>
                <body name="iiwa14_link5" pos="0 0.1845 0" quat="0 0 0.707107 0.707107">
                  <inertial pos="0.0001 0.021 0.076" mass="3.5" diaginertia="0.01 0.0087 0.00449"/>
                  <joint name="iiwa14_joint5" class="iiwa14_joint1" pos="0 0 0" axis="0 0 1"/>
                  <geom class="iiwa14_visual" material="iiwa14_gray" mesh="iiwa14_link_5"/>
                  <geom class="iiwa14_visual" material="iiwa14_light_gray" mesh="iiwa14_band"/>
                  <geom class="iiwa14_visual" material="iiwa14_black" mesh="iiwa14_kuka"/>
                  <geom class="iiwa14_collision" size="0.075" pos="0 0 0.0335"/>
                  <geom class="iiwa14_collision" size="0.05" pos="-0.012 0.031 0.0755"/>
                  <geom class="iiwa14_collision" size="0.05" pos="0.012 0.031 0.0755"/>
                  <geom class="iiwa14_collision" size="0.04" pos="-0.012 0.06 0.1155"/>
                  <geom class="iiwa14_collision" size="0.04" pos="0.012 0.06 0.1155"/>
                  <geom class="iiwa14_collision" size="0.04" pos="-0.01 0.065 0.1655"/>
                  <geom class="iiwa14_collision" size="0.04" pos="0.01 0.065 0.1655"/>
                  <geom class="iiwa14_collision" size="0.035" pos="-0.012 0.065 0.1855"/>
                  <geom class="iiwa14_collision" size="0.035" pos="0.012 0.065 0.1855"/>
                  <body name="iiwa14_link6" pos="0 0 0.2155" quat="0.707107 0.707107 0 0">
                    <inertial pos="0 0.0006 0.0004" quat="0.707107 0.707107 0 0" mass="1.8" diaginertia="0.0049 0.0047 0.0036"/>
                    <joint name="iiwa14_joint6" class="iiwa14_joint2" pos="0 0 0" axis="0 0 1"/>
                    <geom class="iiwa14_visual" material="iiwa14_orange" mesh="iiwa14_link_6_orange"/>
                    <geom class="iiwa14_visual" material="iiwa14_gray" mesh="iiwa14_link_6_grey"/>
                    <geom class="iiwa14_collision" size="0.055" pos="0 0 -0.059"/>
                    <geom class="iiwa14_collision" size="0.065" pos="0 -0.03 0.011"/>
                    <geom class="iiwa14_collision" size="0.08"/>
                    <body name="iiwa14_link7" pos="0 0.081 0" quat="0 0 0.707107 0.707107">
                      <inertial pos="0 0 0.02" mass="1.2" diaginertia="0.001 0.001 0.001"/>
                      <joint name="iiwa14_joint7" class="iiwa14_joint3" pos="0 0 0" axis="0 0 1"/>
                      <geom class="iiwa14_visual" material="iiwa14_gray" mesh="iiwa14_link_7"/>
                      <geom class="iiwa14_collision" size="0.06" pos="0 0 0.001"/>
                      <body name="iiwa14_flange" pos="0 0 0.045">
                        <inertial pos="0 0 0.045" quat="0.707107 0 -0.707107 0" mass="0" diaginertia="0 0 0"/>
                        <site pos="0.125 0 0" quat="0.707107 0 0.707107 0" size="0.005 0.125" group="3" type="cylinder"/>
                        <site pos="0 0.125 0" quat="0.707107 0.707107 0 0" size="0.005 0.125" group="3" type="cylinder" rgba="0 1 0 1"/>
                        <site pos="0 0 0.125" size="0.005 0.125" group="3" type="cylinder" rgba="0 0 1 1"/>
                        <site name="iiwa14_flange" pos="0 0 0"/>
                        <site name="iiwa14_TCP" pos="0 0 0"/>
                      </body>
                    </body>
                  </body>
                </body>
              </body>
            </body>
          </body>
        </body>
      </body>
    </body>
  </worldbody>

  <contact>
    <exclude body1="iiwa14_link0" body2="iiwa14_link1"/>
    <exclude body1="iiwa14_link0" body2="iiwa14_link2"/>
    <exclude body1="iiwa14_link0" body2="iiwa14_link3"/>
    <exclude body1="iiwa14_link1" body2="iiwa14_link3"/>
    <exclude body1="iiwa14_link3" body2="iiwa14_link5"/>
    <exclude body1="iiwa14_link4" body2="iiwa14_link7"/>
    <exclude body1="iiwa14_link5" body2="iiwa14_link7"/>
  </contact>

  <actuator>
    <general name="iiwa14_actuator1" class="iiwa14_joint1" joint="iiwa14_joint1"/>
    <general name="iiwa14_actuator2" class="iiwa14_joint2" joint="iiwa14_joint2"/>
    <general name="iiwa14_actuator3" class="iiwa14_joint1" joint="iiwa14_joint3"/>
    <general name="iiwa14_actuator4" class="iiwa14_joint2" joint="iiwa14_joint4"/>
    <general name="iiwa14_actuator5" class="iiwa14_joint1" joint="iiwa14_joint5"/>
    <general name="iiwa14_actuator6" class="iiwa14_joint2" joint="iiwa14_joint6"/>
    <general name="iiwa14_actuator7" class="iiwa14_joint3" joint="iiwa14_joint7"/>
  </actuator>

  <sensor>
    <framepos objtype="site" objname="iiwa14_TCP" name="iiwa14_pos"/>
    <framequat objtype="site" objname="iiwa14_TCP" name="iiwa14_ori"/>
    <framelinvel objtype="site" objname="iiwa14_TCP" name="iiwa14_v"/>
    <frameangvel objtype="site" objname="iiwa14_TCP" name="iiwa14_w"/>
    <force site="iiwa14_TCP" name="iiwa14_force" noise="0.5"/>
    <torque site="iiwa14_TCP" name="iiwa14_torque" noise="0.5"/>
    <jointpos joint="iiwa14_joint1" name="iiwa14_pos_joint1"/>
    <jointpos joint="iiwa14_joint2" name="iiwa14_pos_joint2"/>
    <jointpos joint="iiwa14_joint3" name="iiwa14_pos_joint3"/>
    <jointpos joint="iiwa14_joint4" name="iiwa14_pos_joint4"/>
    <jointpos joint="iiwa14_joint5" name="iiwa14_pos_joint5"/>
    <jointpos joint="iiwa14_joint6" name="iiwa14_pos_joint6"/>
    <jointpos joint="iiwa14_joint7" name="iiwa14_pos_joint7"/>
    <jointvel joint="iiwa14_joint1" name="iiwa14_vel_joint1"/>
    <jointvel joint="iiwa14_joint2" name="iiwa14_vel_joint2"/>
    <jointvel joint="iiwa14_joint3" name="iiwa14_vel_joint3"/>
    <jointvel joint="iiwa14_joint4" name="iiwa14_vel_joint4"/>
    <jointvel joint="iiwa14_joint5" name="iiwa14_vel_joint5"/>
    <jointvel joint="iiwa14_joint6" name="iiwa14_vel_joint6"/>
    <jointvel joint="iiwa14_joint7" name="iiwa14_vel_joint7"/>
  </sensor>

  <keyframe>
    <key name="iiwa14_home" qpos="0 0.785398 0 -1.5708 0 0 0" ctrl="0 0.785398 0 -1.5708 0 0 0"/>
  </keyframe>
</mujoco>
