<mujoco model="mir100_scene">
  <compiler angle="radian" meshdir="assets/" texturedir="assets/"/>

  <option timestep="0.001" integrator="implicitfast"/>

  <visual>
    <global offwidth="1280" offheight="960"/>
    <map stiffness="700" fogstart="1" fogend="15" zfar="40" haze="1" shadowscale="0.5"/>
    <rgba haze="0.15 0.25 0.35 1"/>
  </visual>

  <statistic meansize="0.05"/>

  <default>
    <geom solref="0.002" margin="0.001"/>
    <light castshadow="false"/>
    <general biastype="affine" biasprm="0 -1"/>
    <default class="mir100_main">
      <geom solref="0.02" margin="0"/>
      <light castshadow="true"/>
      <general biastype="none" biasprm="0 0"/>
      <default class="mir100_mir">
        <material shininess="0.25"/>
        <joint limited="false" armature="0.1" damping="1"/>
        <geom contype="0"/>
        <site size="0.01 0.005 0.005" group="1" rgba="1 0 0 1"/>
        <default class="mir100_visual">
          <geom type="mesh" conaffinity="0" group="2"/>
        </default>
        <default class="mir100_collision">
          <geom type="mesh" group="3"/>
        </default>
      </default>
    </default>
  </default>

  <asset>
    <texture type="skybox" colorspace="auto" builtin="gradient" rgb1="0.3 0.5 0.7" rgb2="0 0 0" width="512" height="3072"/>
    <texture type="2d" colorspace="auto" name="texplane" builtin="checker" mark="cross" rgb1="0.2 0.3 0.4" rgb2="0.1 0.15 0.2" markrgb="0.8 0.8 0.8" width="512" height="512"/>
    <material name="matplane" texture="texplane" texuniform="true" texrepeat="10 10" reflectance="0.3"/>
    <material name="mir100_white" class="mir100_mir"/>
    <material name="mir100_off_white" class="mir100_mir" rgba="0.901961 0.921569 0.929412 1"/>
    <material name="mir100_black" class="mir100_mir" rgba="0.1 0.1 0.1 1"/>
    <material name="mir100_green" class="mir100_mir" rgba="0 1 0 1"/>
    <material name="mir100_light_gray" class="mir100_mir" rgba="0.79 0.82 0.93 1"/>
    <mesh name="mir100_mir_100_base_c" content_type="model/stl" file="MiR100/mir_100_base_c.stl"/>
    <mesh name="mir100_caster_wheel_base_c" content_type="model/stl" file="MiR100/caster_wheel_base_c.stl"/>
    <mesh name="mir100_mir_100_base" content_type="model/stl" file="MiR100/mir_100_base.stl"/>
    <mesh name="mir100_sick_lms-100" content_type="model/stl" file="MiR100/sick_lms-100.stl"/>
    <mesh name="mir100_caster_wheel_base" content_type="model/stl" file="MiR100/caster_wheel_base.stl"/>
  </asset>

  <worldbody>
    <geom name="ground" size="0 0 1" type="plane" condim="1" material="matplane"/>
    <site pos="0.5 0 0" quat="0.707107 0 0.707107 0" size="0.005 0.5" type="cylinder" rgba="1 0 0 1"/>
    <site pos="0 0.5 0" quat="0.707107 0.707107 0 0" size="0.005 0.5" type="cylinder" rgba="0 1 0 1"/>
    <site pos="0 0 0.5" size="0.005 0.5" type="cylinder" rgba="0 0 1 1"/>
    <light pos="0 0 2" dir="0 0 -1" diffuse="0.4 0.4 0.4" specular="0.1 0.1 0.1"/>
    <light pos="0 0 4" dir="0 0 -1" type="directional" diffuse="0.8 0.8 0.8" specular="0.2 0.2 0.2"/>
    <body name="Target" mocap="true">
      <site pos="0.05 0 0" quat="0.707107 0 0.707107 0" size="0.002 0.05" group="4" type="cylinder" rgba="1 0 0 1"/>
      <site pos="0 0.05 0" quat="0.707107 0.707107 0 0" size="0.002 0.05" group="4" type="cylinder" rgba="0 1 0 1"/>
      <site pos="0 0 0.05" size="0.002 0.05" group="4" type="cylinder" rgba="0 0 1 1"/>
      <site name="Target" pos="0 0 0" size="0.01" group="1" rgba="1 0.5 1 0.5"/>
    </body>
    <body name="mir100" childclass="mir100_mir">
      <joint type="free"/>
      <geom class="mir100_visual" pos="0.037646 0 0" quat="1 0 0 0" material="mir100_white" mesh="mir100_mir_100_base"/>
      <geom class="mir100_visual" pos="0.429646 0.2358 0.1914" quat="0 0.92388 0.382683 0" material="mir100_black" mesh="mir100_sick_lms-100"/>
      <geom class="mir100_visual" pos="-0.354354 -0.2358 0.1914" quat="0 0.382683 -0.92388 0" material="mir100_black" mesh="mir100_sick_lms-100"/>
      <geom class="mir100_collision" pos="0.037646 0 0" quat="1 0 0 0" material="mir100_white" mesh="mir100_mir_100_base_c"/>
      <site pos="0.25 0 0" quat="0.707107 0 0.707107 0" size="0.01 0.25" group="2" type="cylinder"/>
      <site pos="0 0.25 0" quat="0.707107 0.707107 0 0" size="0.01 0.25" group="2" type="cylinder" rgba="0 1 0 1"/>
      <site pos="0 0 0.25" size="0.01 0.25" group="2" type="cylinder" rgba="0 0 1 1"/>
      <body name="mir100_right_wheel_link" pos="0 -0.222604 0.0625">
        <inertial pos="0 0 0" quat="0.5 0.5 -0.5 0.5" mass="1" diaginertia="0.00195312 0.0010619 0.0010619"/>
        <joint name="mir100_joint1" pos="0 0 0" axis="0 1 0" actuatorfrcrange="-100 100"/>
        <geom size="0.0625 0.016" quat="0.707107 0.707107 0 0" type="cylinder" group="1" material="mir100_black"/>
        <site pos="0 0 -0.0625"/>
      </body>
      <body name="mir100_left_wheel_link" pos="0 0.222604 0.0625">
        <inertial pos="0 0 0" quat="0.5 0.5 -0.5 0.5" mass="1" diaginertia="0.00195312 0.0010619 0.0010619"/>
        <joint name="mir100_joint2" pos="0 0 0" axis="0 1 0" actuatorfrcrange="-100 100"/>
        <geom size="0.0625 0.016" quat="0.707107 0.707107 0 0" type="cylinder" group="1" material="mir100_black"/>
        <site pos="0 0 -0.0625"/>
      </body>
      <body name="mir100_fl_caster_rotation_link" pos="0.341346 0.203 0.1565">
        <inertial pos="0 0 -0.0425" mass="0.309754" diaginertia="0.000584452 0.000528726 0.000179236"/>
        <joint name="mir100_fl_caster_rotation_joint" pos="0 0 0" axis="0 0 1" damping="0.01"/>
        <geom class="mir100_visual" material="mir100_light_gray" mesh="mir100_caster_wheel_base"/>
        <geom class="mir100_collision" material="mir100_light_gray" mesh="mir100_caster_wheel_base_c"/>
        <body name="mir100_fl_caster_wheel_link" pos="-0.0382 0 -0.094">
          <inertial pos="0 0 0" quat="0.5 0.5 -0.5 0.5" mass="1" diaginertia="0.00195312 0.0010619 0.0010619"/>
          <joint name="mir100_fl_caster_wheel_joint" pos="0 0 0" axis="0 1 0"/>
          <geom size="0.0625 0.016" quat="0.707107 0.707107 0 0" type="cylinder" material="mir100_black"/>
        </body>
      </body>
      <body name="mir100_fr_caster_rotation_link" pos="0.341346 -0.203 0.1565">
        <inertial pos="0 0 -0.0425" mass="0.309754" diaginertia="0.000584452 0.000528726 0.000179236"/>
        <joint name="mir100_fr_caster_rotation_joint" pos="0 0 0" axis="0 0 1" damping="0.01"/>
        <geom class="mir100_visual" material="mir100_light_gray" mesh="mir100_caster_wheel_base"/>
        <geom class="mir100_collision" material="mir100_light_gray" mesh="mir100_caster_wheel_base_c"/>
        <body name="mir100_fr_caster_wheel_link" pos="-0.0382 0 -0.094">
          <inertial pos="0 0 0" quat="0.5 0.5 -0.5 0.5" mass="1" diaginertia="0.00195312 0.0010619 0.0010619"/>
          <joint name="mir100_fr_caster_wheel_joint" pos="0 0 0" axis="0 1 0"/>
          <geom size="0.0625 0.016" quat="0.707107 0.707107 0 0" type="cylinder" group="1" material="mir100_black"/>
        </body>
      </body>
      <body name="mir100_bl_caster_rotation_link" pos="-0.270154 0.203 0.1565">
        <inertial pos="0 0 -0.0425" mass="0.309754" diaginertia="0.000584452 0.000528726 0.000179236"/>
        <joint name="mir100_bl_caster_rotation_joint" pos="0 0 0" axis="0 0 1" damping="0.01"/>
        <geom class="mir100_visual" material="mir100_light_gray" mesh="mir100_caster_wheel_base"/>
        <geom class="mir100_collision" material="mir100_light_gray" mesh="mir100_caster_wheel_base_c"/>
        <body name="mir100_bl_caster_wheel_link" pos="-0.0382 0 -0.094">
          <inertial pos="0 0 0" quat="0.5 0.5 -0.5 0.5" mass="1" diaginertia="0.00195312 0.0010619 0.0010619"/>
          <joint name="mir100_bl_caster_wheel_joint" pos="0 0 0" axis="0 1 0"/>
          <geom size="0.0625 0.016" quat="0.707107 0.707107 0 0" type="cylinder" group="1" material="mir100_black"/>
        </body>
      </body>
      <body name="mir100_br_caster_rotation_link" pos="-0.270154 -0.203 0.1565">
        <inertial pos="0 0 -0.0425" mass="0.309754" diaginertia="0.000584452 0.000528726 0.000179236"/>
        <joint name="mir100_br_caster_rotation_joint" pos="0 0 0" axis="0 0 1" damping="0.01"/>
        <geom class="mir100_visual" material="mir100_light_gray" mesh="mir100_caster_wheel_base"/>
        <geom class="mir100_collision" material="mir100_light_gray" mesh="mir100_caster_wheel_base_c"/>
        <body name="mir100_br_caster_wheel_link" pos="-0.0382 0 -0.094">
          <inertial pos="0 0 0" quat="0.5 0.5 -0.5 0.5" mass="1" diaginertia="0.00195312 0.0010619 0.0010619"/>
          <joint name="mir100_br_caster_wheel_joint" pos="0 0 0" axis="0 1 0"/>
          <geom size="0.0625 0.016" quat="0.707107 0.707107 0 0" type="cylinder" group="1" material="mir100_black"/>
        </body>
      </body>
    </body>
  </worldbody>

  <actuator>
    <general name="mir100_actuator1" class="mir100_mir" joint="mir100_joint1" ctrlrange="-4.8 24" biastype="affine" gainprm="1000" biasprm="0 0 -1000"/>
    <general name="mir100_actuator2" class="mir100_mir" joint="mir100_joint2" ctrlrange="-4.8 24" biastype="affine" gainprm="1000" biasprm="0 0 -1000"/>
  </actuator>
</mujoco>
