<mujoco model="panda_box_e">
  <compiler angle="radian" meshdir="assets/" texturedir="assets/"/>

  <option timestep="0.001" integrator="implicitfast"/>

  <size nkey="1"/>

  <visual>
    <global offwidth="1280" offheight="960"/>
    <map stiffness="700" fogstart="1" fogend="15" zfar="40" haze="1" shadowscale="0.5"/>
    <rgba haze="0.15 0.25 0.35 1"/>
  </visual>

  <statistic meansize="0.05"/>

  <default>
    <geom solref="0.002" margin="0.001"/>
    <light castshadow="false"/>
    <general biastype="affine" biasprm="0 -1"/>
    <default class="panda_main">
      <geom solref="0.02" margin="0"/>
      <light castshadow="true"/>
      <general biastype="none" biasprm="0 0"/>
      <default class="panda_robot">
        <material shininess="0.25"/>
        <joint range="-2.8973 2.8973" armature="0.1" damping="1"/>
        <site size="0.001 0.005 0.005" group="4" rgba="0.5 0.5 0.5 0.3"/>
        <general ctrlrange="-2.8973 2.8973" forcerange="-87 87" biastype="affine"/>
        <default class="panda_finger">
          <joint type="slide" range="0 0.04"/>
        </default>
        <default class="panda_visual">
          <geom type="mesh" contype="0" conaffinity="0" group="2"/>
        </default>
        <default class="panda_collision">
          <geom type="mesh" group="3"/>
          <default class="panda_fingertip_pad_collision_1">
            <geom size="0.0085 0.004 0.0085" type="box"/>
          </default>
          <default class="panda_fingertip_pad_collision_2">
            <geom size="0.003 0.002 0.003" type="box"/>
          </default>
          <default class="panda_fingertip_pad_collision_3">
            <geom size="0.003 0.002 0.003" type="box"/>
          </default>
          <default class="panda_fingertip_pad_collision_4">
            <geom size="0.003 0.002 0.0035" type="box"/>
          </default>
          <default class="panda_fingertip_pad_collision_5">
            <geom size="0.003 0.002 0.0035" type="box"/>
          </default>
        </default>
      </default>
    </default>
  </default>

  <asset>
    <texture type="skybox" colorspace="auto" builtin="gradient" rgb1="0.3 0.5 0.7" rgb2="0 0 0" width="512" height="3072"/>
    <texture type="2d" colorspace="auto" name="texplane" builtin="checker" mark="cross" rgb1="0.2 0.3 0.4" rgb2="0.1 0.15 0.2" markrgb="0.8 0.8 0.8" width="512" height="512"/>
    <material name="matplane" texture="texplane" texuniform="true" texrepeat="10 10" reflectance="0.3"/>
    <material name="panda_white" class="panda_robot"/>
    <material name="panda_off_white" class="panda_robot" rgba="0.901961 0.921569 0.929412 1"/>
    <material name="panda_dark_grey" class="panda_robot" rgba="0.25 0.25 0.25 1"/>
    <material name="panda_green" class="panda_robot" rgba="0 1 0 1"/>
    <material name="panda_light_blue" class="panda_robot" rgba="0.039216 0.541176 0.780392 1"/>
    <material name="panda_black" class="panda_robot" rgba="0.25 0.25 0.25 1"/>
    <mesh name="panda_link0_c" file="panda/link0.stl"/>
    <mesh name="panda_link1_c" file="panda/link1.stl"/>
    <mesh name="panda_link2_c" file="panda/link2.stl"/>
    <mesh name="panda_link3_c" file="panda/link3.stl"/>
    <mesh name="panda_link4_c" file="panda/link4.stl"/>
    <mesh name="panda_link5_c0" file="panda/link5_collision_0.obj"/>
    <mesh name="panda_link5_c1" file="panda/link5_collision_1.obj"/>
    <mesh name="panda_link5_c2" file="panda/link5_collision_2.obj"/>
    <mesh name="panda_link6_c" file="panda/link6.stl"/>
    <mesh name="panda_link7_c" file="panda/link7.stl"/>
    <mesh name="panda_hand_c" file="panda/hand.stl"/>
    <mesh name="panda_link0_0" file="panda/link0_0.obj"/>
    <mesh name="panda_link0_1" file="panda/link0_1.obj"/>
    <mesh name="panda_link0_2" file="panda/link0_2.obj"/>
    <mesh name="panda_link0_3" file="panda/link0_3.obj"/>
    <mesh name="panda_link0_4" file="panda/link0_4.obj"/>
    <mesh name="panda_link0_5" file="panda/link0_5.obj"/>
    <mesh name="panda_link0_7" file="panda/link0_7.obj"/>
    <mesh name="panda_link0_8" file="panda/link0_8.obj"/>
    <mesh name="panda_link0_9" file="panda/link0_9.obj"/>
    <mesh name="panda_link0_10" file="panda/link0_10.obj"/>
    <mesh name="panda_link0_11" file="panda/link0_11.obj"/>
    <mesh name="panda_link1" file="panda/link1.obj"/>
    <mesh name="panda_link2" file="panda/link2.obj"/>
    <mesh name="panda_link3_0" file="panda/link3_0.obj"/>
    <mesh name="panda_link3_1" file="panda/link3_1.obj"/>
    <mesh name="panda_link3_2" file="panda/link3_2.obj"/>
    <mesh name="panda_link3_3" file="panda/link3_3.obj"/>
    <mesh name="panda_link4_0" file="panda/link4_0.obj"/>
    <mesh name="panda_link4_1" file="panda/link4_1.obj"/>
    <mesh name="panda_link4_2" file="panda/link4_2.obj"/>
    <mesh name="panda_link4_3" file="panda/link4_3.obj"/>
    <mesh name="panda_link5_0" file="panda/link5_0.obj"/>
    <mesh name="panda_link5_1" file="panda/link5_1.obj"/>
    <mesh name="panda_link5_2" file="panda/link5_2.obj"/>
    <mesh name="panda_link6_0" file="panda/link6_0.obj"/>
    <mesh name="panda_link6_1" file="panda/link6_1.obj"/>
    <mesh name="panda_link6_2" file="panda/link6_2.obj"/>
    <mesh name="panda_link6_3" file="panda/link6_3.obj"/>
    <mesh name="panda_link6_4" file="panda/link6_4.obj"/>
    <mesh name="panda_link6_5" file="panda/link6_5.obj"/>
    <mesh name="panda_link6_6" file="panda/link6_6.obj"/>
    <mesh name="panda_link6_7" file="panda/link6_7.obj"/>
    <mesh name="panda_link6_8" file="panda/link6_8.obj"/>
    <mesh name="panda_link6_9" file="panda/link6_9.obj"/>
    <mesh name="panda_link6_10" file="panda/link6_10.obj"/>
    <mesh name="panda_link6_11" file="panda/link6_11.obj"/>
    <mesh name="panda_link6_12" file="panda/link6_12.obj"/>
    <mesh name="panda_link6_13" file="panda/link6_13.obj"/>
    <mesh name="panda_link6_14" file="panda/link6_14.obj"/>
    <mesh name="panda_link6_15" file="panda/link6_15.obj"/>
    <mesh name="panda_link6_16" file="panda/link6_16.obj"/>
    <mesh name="panda_link7_0" file="panda/link7_0.obj"/>
    <mesh name="panda_link7_1" file="panda/link7_1.obj"/>
    <mesh name="panda_link7_2" file="panda/link7_2.obj"/>
    <mesh name="panda_link7_3" file="panda/link7_3.obj"/>
    <mesh name="panda_link7_4" file="panda/link7_4.obj"/>
    <mesh name="panda_link7_5" file="panda/link7_5.obj"/>
    <mesh name="panda_link7_6" file="panda/link7_6.obj"/>
    <mesh name="panda_link7_7" file="panda/link7_7.obj"/>
    <mesh name="panda_hand_0" file="panda/hand_0.obj"/>
    <mesh name="panda_hand_1" file="panda/hand_1.obj"/>
    <mesh name="panda_hand_2" file="panda/hand_2.obj"/>
    <mesh name="panda_hand_3" file="panda/hand_3.obj"/>
    <mesh name="panda_hand_4" file="panda/hand_4.obj"/>
    <mesh name="panda_finger_0" file="panda/finger_0.obj"/>
    <mesh name="panda_finger_1" file="panda/finger_1.obj"/>
  </asset>

  <worldbody>
    <geom name="ground" size="0 0 1" type="plane" condim="1" material="matplane"/>
    <site pos="0.5 0 0" quat="0.707107 0 0.707107 0" size="0.005 0.5" type="cylinder" rgba="1 0 0 1"/>
    <site pos="0 0.5 0" quat="0.707107 0.707107 0 0" size="0.005 0.5" type="cylinder" rgba="0 1 0 1"/>
    <site pos="0 0 0.5" size="0.005 0.5" type="cylinder" rgba="0 0 1 1"/>
    <light pos="0 0 2" dir="0 0 -1" diffuse="0.4 0.4 0.4" specular="0.1 0.1 0.1"/>
    <light pos="0 0 4" dir="0 0 -1" type="directional" diffuse="0.8 0.8 0.8" specular="0.2 0.2 0.2"/>
    <body name="Target" mocap="true">
      <site pos="0.05 0 0" quat="0.707107 0 0.707107 0" size="0.002 0.05" group="4" type="cylinder" rgba="1 0 0 1"/>
      <site pos="0 0.05 0" quat="0.707107 0.707107 0 0" size="0.002 0.05" group="4" type="cylinder" rgba="0 1 0 1"/>
      <site pos="0 0 0.05" size="0.002 0.05" group="4" type="cylinder" rgba="0 0 1 1"/>
      <site name="Target" pos="0 0 0" size="0.01" group="1" rgba="1 0.5 1 0.5"/>
    </body>
    <body name="Box" pos="0.5 0 0.05" axisangle="1 0 0 0">
      <site group="5" type="cylinder" pos="0.05 0 0  " quat="0.70711 0 0.70711 0" size="0.01 0.05" rgba="1 0 0 1"/>
      <site group="5" type="cylinder" pos="0 0.05 0  " quat="0.70711 0.70711 0 0" size="0.01 0.05" rgba="0 1 0 1"/>
      <site group="5" type="cylinder" pos="0 0   0.05" quat="1 0 0 0"             size="0.01 0.05" rgba="0 0 1 1"/>
      <geom name="Box" group="1" type="box" pos="0 0 0" size="0.02 0.02 0.02" solref="-100 -100" friction="1 0.9 0.9" rgba="0 0 1 1"/>
      <joint name="Box" type="free" />
      <site group="1" name="Box" type="sphere" pos="0 0 0" size="0.001" rgba="0.5 .5 1 0.5"/>
    </body>
    <body name="Load" pos="0.7 0 0.05" axisangle="1 0 0 0">
      <geom name="Load" group="1" type="box" pos="0 0 0" size="0.03 0.03 0.03" density="5000" solref="-100 -100" friction="1 0 0" rgba="0 1 1 1"/>
      <joint name="Load" type="free" />
      <site group="2" name="Load" type="sphere" pos="0 0 -0.1" size="0.01" rgba="1 1 0 0.5"/>
    </body>
    <body name="panda" childclass="panda_robot">
      <site name="panda_x" pos="0.25 0 0" quat="0.707107 0 0.707107 0" size="0.01 0.25" group="1" type="cylinder" rgba="1 0 0 1"/>
      <site name="panda_y" pos="0 0.25 0" quat="0.707107 0.707107 0 0" size="0.01 0.25" group="1" type="cylinder" rgba="0 1 0 1"/>
      <site name="panda_z" pos="0 0 0.25" size="0.01 0.25" group="1" type="cylinder" rgba="0 0 1 1"/>
      <body name="panda_link0">
        <inertial pos="-0.041018 -0.00014 0.049974" quat="0.00630474 0.751245 0.00741774 0.659952" mass="0.629769" diaginertia="0.00430465 0.00387984 0.00313051"/>
        <geom class="panda_visual" material="panda_off_white" mesh="panda_link0_0"/>
        <geom class="panda_visual" material="panda_dark_grey" mesh="panda_link0_1"/>
        <geom class="panda_visual" material="panda_off_white" mesh="panda_link0_2"/>
        <geom class="panda_visual" material="panda_dark_grey" mesh="panda_link0_3"/>
        <geom class="panda_visual" material="panda_off_white" mesh="panda_link0_4"/>
        <geom class="panda_visual" material="panda_dark_grey" mesh="panda_link0_5"/>
        <geom class="panda_visual" material="panda_white" mesh="panda_link0_7"/>
        <geom class="panda_visual" material="panda_white" mesh="panda_link0_8"/>
        <geom class="panda_visual" material="panda_dark_grey" mesh="panda_link0_9"/>
        <geom class="panda_visual" material="panda_off_white" mesh="panda_link0_10"/>
        <geom class="panda_visual" material="panda_white" mesh="panda_link0_11"/>
        <geom class="panda_collision" mesh="panda_link0_c"/>
        <body name="panda_link1" pos="0 0 0.333">
          <inertial pos="0.003875 0.002081 -0.04762" quat="0.711549 0.00634377 -0.0131124 0.702485" mass="4.97068" diaginertia="0.707137 0.703435 0.00852456"/>
          <joint name="panda_joint1" pos="0 0 0" axis="0 0 1"/>
          <geom class="panda_visual" material="panda_white" mesh="panda_link1"/>
          <geom class="panda_collision" mesh="panda_link1_c"/>
          <body name="panda_link2" quat="0.707107 -0.707107 0 0">
            <inertial pos="-0.003141 -0.02872 0.003495" quat="-0.168175 0.828366 -0.122878 0.520027" mass="0.646926" diaginertia="0.0310326 0.0283001 0.00273425"/>
            <joint name="panda_joint2" pos="0 0 0" axis="0 0 1" range="-1.7628 1.7628"/>
            <geom class="panda_visual" material="panda_white" mesh="panda_link2"/>
            <geom class="panda_collision" mesh="panda_link2_c"/>
            <body name="panda_link3" pos="0 -0.316 0" quat="0.707107 0.707107 0 0">
              <inertial pos="0.027518 0.039252 -0.066502" quat="0.662769 -0.00678331 0.252053 0.705096" mass="3.2286" diaginertia="0.0415014 0.0414793 0.00124635"/>
              <joint name="panda_joint3" pos="0 0 0" axis="0 0 1"/>
              <geom class="panda_visual" material="panda_white" mesh="panda_link3_0"/>
              <geom class="panda_visual" material="panda_white" mesh="panda_link3_1"/>
              <geom class="panda_visual" material="panda_white" mesh="panda_link3_2"/>
              <geom class="panda_visual" material="panda_dark_grey" mesh="panda_link3_3"/>
              <geom class="panda_collision" mesh="panda_link3_c"/>
              <body name="panda_link4" pos="0.0825 0 0" quat="0.707107 0.707107 0 0">
                <inertial pos="-0.05317 0.104419 0.027454" quat="0.65058 0.529822 -0.0962034 0.535518" mass="3.5879" diaginertia="0.0349596 0.0281483 0.0106201"/>
                <joint name="panda_joint4" pos="0 0 0" axis="0 0 1" range="-3.0718 -0.0698"/>
                <geom class="panda_visual" material="panda_white" mesh="panda_link4_0"/>
                <geom class="panda_visual" material="panda_white" mesh="panda_link4_1"/>
                <geom class="panda_visual" material="panda_dark_grey" mesh="panda_link4_2"/>
                <geom class="panda_visual" material="panda_white" mesh="panda_link4_3"/>
                <geom class="panda_collision" mesh="panda_link4_c"/>
                <body name="panda_link5" pos="-0.0825 0.384 0" quat="0.707107 -0.707107 0 0">
                  <inertial pos="-0.011953 0.041065 -0.038437" quat="0.987313 -0.0121954 0.0719187 -0.141037" mass="1.22595" diaginertia="0.0367625 0.0288531 0.00803437"/>
                  <joint name="panda_joint5" pos="0 0 0" axis="0 0 1"/>
                  <geom class="panda_visual" material="panda_dark_grey" mesh="panda_link5_0"/>
                  <geom class="panda_visual" material="panda_white" mesh="panda_link5_1"/>
                  <geom class="panda_visual" material="panda_white" mesh="panda_link5_2"/>
                  <geom class="panda_collision" mesh="panda_link5_c0"/>
                  <geom class="panda_collision" mesh="panda_link5_c1"/>
                  <geom class="panda_collision" mesh="panda_link5_c2"/>
                  <body name="panda_link6" quat="0.707107 0.707107 0 0">
                    <inertial pos="0.060149 -0.014117 -0.010517" quat="0.101075 0.59332 0.0287227 0.798079" mass="1.66656" diaginertia="0.00584276 0.00431037 0.00159787"/>
                    <joint name="panda_joint6" pos="0 0 0" axis="0 0 1" range="-0.0175 3.7525"/>
                    <geom class="panda_visual" material="panda_off_white" mesh="panda_link6_0"/>
                    <geom class="panda_visual" material="panda_white" mesh="panda_link6_1"/>
                    <geom class="panda_visual" material="panda_dark_grey" mesh="panda_link6_2"/>
                    <geom class="panda_visual" material="panda_white" mesh="panda_link6_3"/>
                    <geom class="panda_visual" material="panda_white" mesh="panda_link6_4"/>
                    <geom class="panda_visual" material="panda_white" mesh="panda_link6_5"/>
                    <geom class="panda_visual" material="panda_white" mesh="panda_link6_6"/>
                    <geom class="panda_visual" material="panda_light_blue" mesh="panda_link6_7"/>
                    <geom class="panda_visual" material="panda_light_blue" mesh="panda_link6_8"/>
                    <geom class="panda_visual" material="panda_dark_grey" mesh="panda_link6_9"/>
                    <geom class="panda_visual" material="panda_dark_grey" mesh="panda_link6_10"/>
                    <geom class="panda_visual" material="panda_white" mesh="panda_link6_11"/>
                    <geom class="panda_visual" material="panda_green" mesh="panda_link6_12"/>
                    <geom class="panda_visual" material="panda_white" mesh="panda_link6_13"/>
                    <geom class="panda_visual" material="panda_dark_grey" mesh="panda_link6_14"/>
                    <geom class="panda_visual" material="panda_dark_grey" mesh="panda_link6_15"/>
                    <geom class="panda_visual" material="panda_white" mesh="panda_link6_16"/>
                    <geom class="panda_collision" mesh="panda_link6_c"/>
                    <body name="panda_link7" pos="0.088 0 0" quat="0.707107 0.707107 0 0">
                      <inertial pos="0.010517 -0.004252 0.061597" quat="0.992939 -0.0762041 0.0733595 -0.0537067" mass="0.735522" diaginertia="0.0127345 0.0101055 0.00451803"/>
                      <joint name="panda_joint7" pos="0 0 0" axis="0 0 1"/>
                      <geom class="panda_visual" material="panda_white" mesh="panda_link7_0"/>
                      <geom class="panda_visual" material="panda_dark_grey" mesh="panda_link7_1"/>
                      <geom class="panda_visual" material="panda_dark_grey" mesh="panda_link7_2"/>
                      <geom class="panda_visual" material="panda_dark_grey" mesh="panda_link7_3"/>
                      <geom class="panda_visual" material="panda_dark_grey" mesh="panda_link7_4"/>
                      <geom class="panda_visual" material="panda_dark_grey" mesh="panda_link7_5"/>
                      <geom class="panda_visual" material="panda_dark_grey" mesh="panda_link7_6"/>
                      <geom class="panda_visual" material="panda_white" mesh="panda_link7_7"/>
                      <geom class="panda_collision" mesh="panda_link7_c"/>
                      <body name="panda_flange" pos="0 0 0.107">
                        <site pos="0.125 0 0" quat="0.707107 0 0.707107 0" size="0.005 0.125" group="3" type="cylinder" rgba="1 0 0 1"/>
                        <site pos="0 0.125 0" quat="0.707107 0.707107 0 0" size="0.005 0.125" group="3" type="cylinder" rgba="0 1 0 1"/>
                        <site pos="0 0 0.125" size="0.005 0.125" group="3" type="cylinder" rgba="0 0 1 1"/>
                        <site name="panda_flange" pos="0 0 0"/>
                        <body name="panda_hand" quat="0.92388 0 0 -0.382683">
                          <inertial pos="-0.01 0 0.03" mass="0.73" diaginertia="0.001 0.0025 0.0017"/>
                          <geom class="panda_visual" material="panda_off_white" mesh="panda_hand_0"/>
                          <geom class="panda_visual" material="panda_black" mesh="panda_hand_1"/>
                          <geom class="panda_visual" material="panda_black" mesh="panda_hand_2"/>
                          <geom class="panda_visual" material="panda_white" mesh="panda_hand_3"/>
                          <geom class="panda_visual" material="panda_off_white" mesh="panda_hand_4"/>
                          <geom class="panda_collision" mesh="panda_hand_c"/>
                          <site pos="0.0625 0 0.1034" quat="0.707107 0 0.707107 0" size="0.005 0.0625" type="cylinder" rgba="1 0 0 1"/>
                          <site pos="0 0.0625 0.1034" quat="0.707107 0.707107 0 0" size="0.005 0.0625" type="cylinder" rgba="0 1 0 1"/>
                          <site pos="0 0 0.1659" size="0.005 0.0625" type="cylinder" rgba="0 0 1 1"/>
                          <site name="panda_TCP" pos="0 0 0.1034" size="0.008"/>
                          <site name="panda_FT" pos="0 0 0" size="0.008"/>
                          <body name="panda_left_finger" pos="0 0 0.0584">
                            <inertial pos="0 0 0" mass="0.015" diaginertia="2.375e-06 2.375e-06 7.5e-07"/>
                            <joint name="panda_finger_joint1" class="panda_finger" pos="0 0 0" axis="0 1 0"/>
                            <geom class="panda_visual" material="panda_off_white" mesh="panda_finger_0"/>
                            <geom class="panda_visual" material="panda_black" mesh="panda_finger_1"/>
                            <geom class="panda_collision" mesh="panda_finger_0"/>
                            <geom class="panda_fingertip_pad_collision_1" pos="0 0.0055 0.0445"/>
                            <geom class="panda_fingertip_pad_collision_2" pos="0.0055 0.002 0.05"/>
                            <geom class="panda_fingertip_pad_collision_3" pos="-0.0055 0.002 0.05"/>
                            <geom class="panda_fingertip_pad_collision_4" pos="0.0055 0.002 0.0395"/>
                            <geom class="panda_fingertip_pad_collision_5" pos="-0.0055 0.002 0.0395"/>
                            <site name="panda_left_finger" pos="0 0 0.045" size="0.01 0.002 0.01" type="ellipsoid"/>
                          </body>
                          <body name="panda_right_finger" pos="0 0 0.0584" quat="0 0 0 1">
                            <inertial pos="0 0 0" mass="0.015" diaginertia="2.375e-06 2.375e-06 7.5e-07"/>
                            <joint name="panda_finger_joint2" class="panda_finger" pos="0 0 0" axis="0 1 0"/>
                            <geom class="panda_visual" material="panda_off_white" mesh="panda_finger_0"/>
                            <geom class="panda_visual" material="panda_black" mesh="panda_finger_1"/>
                            <geom class="panda_collision" mesh="panda_finger_0"/>
                            <geom class="panda_fingertip_pad_collision_1" pos="0 0.0055 0.0445"/>
                            <geom class="panda_fingertip_pad_collision_2" pos="0.0055 0.002 0.05"/>
                            <geom class="panda_fingertip_pad_collision_3" pos="-0.0055 0.002 0.05"/>
                            <geom class="panda_fingertip_pad_collision_4" pos="0.0055 0.002 0.0395"/>
                            <geom class="panda_fingertip_pad_collision_5" pos="-0.0055 0.002 0.0395"/>
                            <site name="panda_right_finger" pos="0 0 0.045" size="0.01 0.002 0.01" type="ellipsoid"/>
                          </body>
                          <camera name="Robot" pos="0.1 0 0" xyaxes="1 0 0 0 -1 0" fovy="45"/>
                          <body name="Panda_tool"  pos="0 0 0.1034">
                            <inertial mass="0.001" pos="0 0 0" diaginertia="1.0e-6 1.0e-6 1.9e-6"/>
                            <site group="5" name="Panda_tool" pos="0 0 0" />
                          </body>
                        </body>
                      </body>
                    </body>
                  </body>
                </body>
              </body>
            </body>
          </body>
        </body>
      </body>
    </body>
  </worldbody>

  <contact>
    <exclude body1="panda_link0" body2="panda_link1"/>
  </contact>

  <equality>
    <joint joint1="panda_finger_joint1" joint2="panda_finger_joint2" polycoef="0 1 0 0 0" solref="0.005" solimp="0.95 0.99"/>
  </equality>

  <tendon>
    <fixed name="panda_split">
      <joint joint="panda_finger_joint1" coef="0.5"/>
      <joint joint="panda_finger_joint2" coef="0.5"/>
    </fixed>
  </tendon>

  <actuator>
    <general name="panda_actuator1" class="panda_robot" joint="panda_joint1" gainprm="4500" biasprm="0 -4500 -450"/>
    <general name="panda_actuator2" class="panda_robot" joint="panda_joint2" ctrlrange="-1.7628 1.7628" gainprm="4500" biasprm="0 -4500 -450"/>
    <general name="panda_actuator3" class="panda_robot" joint="panda_joint3" gainprm="3500" biasprm="0 -3500 -350"/>
    <general name="panda_actuator4" class="panda_robot" joint="panda_joint4" ctrlrange="-3.0718 -0.0698" gainprm="3500" biasprm="0 -3500 -350"/>
    <general name="panda_actuator5" class="panda_robot" joint="panda_joint5" forcerange="-12 12" gainprm="2000" biasprm="0 -2000 -200"/>
    <general name="panda_actuator6" class="panda_robot" joint="panda_joint6" ctrlrange="-0.0175 3.7525" forcerange="-12 12" gainprm="2000" biasprm="0 -2000 -200"/>
    <general name="panda_actuator7" class="panda_robot" joint="panda_joint7" forcerange="-12 12" gainprm="2000" biasprm="0 -2000 -200"/>
    <general name="panda_gripper" class="panda_robot" tendon="panda_split" ctrlrange="0 0.08" forcerange="-100 100" gainprm="50" biasprm="0 -100 -10"/>
  </actuator>

  <sensor>
    <framepos objtype="site" objname="panda_TCP" name="panda_pos"/>
    <framequat objtype="site" objname="panda_TCP" name="panda_ori"/>
    <framelinvel objtype="site" objname="panda_TCP" name="panda_v"/>
    <frameangvel objtype="site" objname="panda_TCP" name="panda_w"/>
    <force site="panda_FT" name="panda_force" noise="0.5"/>
    <torque site="panda_FT" name="panda_torque" noise="0.5"/>
    <touch site="panda_left_finger" name="panda_left_finger_touch"/>
    <touch site="panda_right_finger" name="panda_right_finger_touch"/>
    <force site="panda_left_finger" name="panda_left_finger_force"/>
    <force site="panda_left_finger" name="panda_right_finger_force"/>
    <jointpos joint="panda_joint1" name="panda_pos_joint1"/>
    <jointpos joint="panda_joint2" name="panda_pos_joint2"/>
    <jointpos joint="panda_joint3" name="panda_pos_joint3"/>
    <jointpos joint="panda_joint4" name="panda_pos_joint4"/>
    <jointpos joint="panda_joint5" name="panda_pos_joint5"/>
    <jointpos joint="panda_joint6" name="panda_pos_joint6"/>
    <jointpos joint="panda_joint7" name="panda_pos_joint7"/>
    <jointvel joint="panda_joint1" name="panda_vel_joint1"/>
    <jointvel joint="panda_joint2" name="panda_vel_joint2"/>
    <jointvel joint="panda_joint3" name="panda_vel_joint3"/>
    <jointvel joint="panda_joint4" name="panda_vel_joint4"/>
    <jointvel joint="panda_joint5" name="panda_vel_joint5"/>
    <jointvel joint="panda_joint6" name="panda_vel_joint6"/>
    <jointvel joint="panda_joint7" name="panda_vel_joint7"/>
  </sensor>

  <equality>
    <weld name="Grasp_box" active="false" site1="Panda_tool" site2="Box"/>
    <weld name="Grasp_load" active="false" site1="Panda_tool" site2="Load"/>
  </equality>
  
  <keyframe>
    <key name="panda_home" qpos="0 0 0 1 0 0 0  0 0 0 1 0 0 0  0 -0.785398 0 -2.35619 0 1.5708 0.785398 0.04 0.04" ctrl="0 -0.785398 0 -2.35619 0 1.5708 0.785398 0.08"/>
  </keyframe>
</mujoco>
