<mujoco model="b2_z1_scene">
  <compiler angle="radian" meshdir="assets/" texturedir="assets/"/>

  <option timestep="0.001" integrator="implicitfast"/>

  <size nkey="1"/>

  <visual>
    <global offwidth="1280" offheight="960"/>
    <map stiffness="700" fogstart="1" fogend="15" zfar="40" haze="1" shadowscale="0.5"/>
    <rgba haze="0.15 0.25 0.35 1"/>
  </visual>

  <statistic meansize="0.05"/>

  <default>
    <geom solref="0.002" margin="0.001"/>
    <light castshadow="false"/>
    <general biastype="affine" biasprm="0 -1"/>
    <default class="b2_main">
      <geom solref="0.02" margin="0"/>
      <light castshadow="true"/>
      <general biastype="none" biasprm="0 0"/>
      <default class="b2_robot">
        <default class="b2_motor">
          <general forcerange="-300 300"/>
        </default>
        <default class="b2_visual">
          <geom contype="0" conaffinity="0" group="1" material="visualgeom"/>
        </default>
        <default class="b2_collision">
          <geom contype="0" group="3" priority="1" friction="3 0.05 0.01" solref="0.005" solimp="0.99 0.999 1e-05" material="collision_material"/>
        </default>
      </default>
    </default>
    <default class="z1_main">
      <geom solref="0.02" margin="0"/>
      <light castshadow="true"/>
      <general biastype="none" biasprm="0 0"/>
      <default class="z1_robot">
        <joint damping="1" frictionloss="1"/>
        <general forcerange="-300 300" biastype="affine" gainprm="500" biasprm="0 -500 -40"/>
        <default class="z1_visual">
          <geom type="mesh" contype="0" conaffinity="0" group="2"/>
        </default>
        <default class="z1_collision">
          <geom type="cylinder" group="3" rgba="1 0.28 0.1 0.9"/>
          <default class="z1_gripper_stator_collision">
            <geom type="mesh"/>
          </default>
          <default class="z1_gripper_stator_pad_collision_1">
            <geom size="0.014 0.015 0.004" type="box"/>
          </default>
          <default class="z1_gripper_stator_pad_collision_2">
            <geom size="0.014 0.015 0.004" type="box"/>
          </default>
          <default class="z1_gripper_mover_collision">
            <geom type="mesh"/>
          </default>
          <default class="z1_gripper_mover_pad_collision_1">
            <geom size="0.014 0.015 0.004" type="box"/>
          </default>
          <default class="z1_gripper_mover_pad_collision_2">
            <geom size="0.014 0.015 0.004" type="box"/>
          </default>
        </default>
      </default>
    </default>
  </default>

  <asset>
    <texture type="skybox" colorspace="auto" builtin="gradient" rgb1="0.3 0.5 0.7" rgb2="0 0 0" width="512" height="3072"/>
    <texture type="2d" colorspace="auto" name="texplane" builtin="checker" mark="cross" rgb1="0.2 0.3 0.4" rgb2="0.1 0.15 0.2" markrgb="0.8 0.8 0.8" width="512" height="512"/>
    <material name="matplane" texture="texplane" texuniform="true" texrepeat="10 10" reflectance="0.3"/>
    <material name="b2_default_material" rgba="0.7 0.7 0.7 1"/>
    <material name="b2_collision_material" rgba="1 0.28 0.1 0.9"/>
    <mesh name="b2_b2_head_collisions" file="unitree_b2/head_collisions.obj"/>
    <mesh name="b2_b2_mainbody_collisions" file="unitree_b2/mainbody_collisions.obj"/>
    <mesh name="b2_base_link_visuals" file="unitree_b2/base_link_visuals.obj"/>
    <mesh name="b2_FL_hip_collisions" file="unitree_b2/FL_hip_collisions.obj"/>
    <mesh name="b2_FL_hip_visuals" file="unitree_b2/FL_hip_visuals.obj"/>
    <mesh name="b2_FL_thigh_collisions" file="unitree_b2/FL_thigh_collisions.obj"/>
    <mesh name="b2_FL_thigh_visuals" file="unitree_b2/FL_thigh_visuals.obj"/>
    <mesh name="b2_FL_calf_collisions" file="unitree_b2/FL_calf_collisions.obj"/>
    <mesh name="b2_FL_calf_visuals" file="unitree_b2/FL_calf_visuals.obj"/>
    <mesh name="b2_FL_foot_collisions_Sphere" file="unitree_b2/FL_foot_collisions_Sphere.obj"/>
    <mesh name="b2_FL_foot_visuals" file="unitree_b2/FL_foot_visuals.obj"/>
    <mesh name="b2_FL_thigh_protect_collisions" file="unitree_b2/FL_thigh_protect_collisions.obj"/>
    <mesh name="b2_FL_thigh_protect_visuals" file="unitree_b2/FL_thigh_protect_visuals.obj"/>
    <mesh name="b2_FR_hip_collisions" file="unitree_b2/FR_hip_collisions.obj"/>
    <mesh name="b2_FR_hip_visuals" file="unitree_b2/FR_hip_visuals.obj"/>
    <mesh name="b2_FR_thigh_collisions" file="unitree_b2/FR_thigh_collisions.obj"/>
    <mesh name="b2_FR_thigh_visuals" file="unitree_b2/FR_thigh_visuals.obj"/>
    <mesh name="b2_FR_calf_collisions" file="unitree_b2/FR_calf_collisions.obj"/>
    <mesh name="b2_FR_calf_visuals" file="unitree_b2/FR_calf_visuals.obj"/>
    <mesh name="b2_FR_foot_collisions_Sphere" file="unitree_b2/FR_foot_collisions_Sphere.obj"/>
    <mesh name="b2_FR_foot_visuals" file="unitree_b2/FR_foot_visuals.obj"/>
    <mesh name="b2_FR_thigh_protect_collisions" file="unitree_b2/FR_thigh_protect_collisions.obj"/>
    <mesh name="b2_FR_thigh_protect_visuals" file="unitree_b2/FR_thigh_protect_visuals.obj"/>
    <mesh name="b2_RL_hip_collisions" file="unitree_b2/RL_hip_collisions.obj"/>
    <mesh name="b2_RL_hip_visuals" file="unitree_b2/RL_hip_visuals.obj"/>
    <mesh name="b2_RL_thigh_collisions" file="unitree_b2/RL_thigh_collisions.obj"/>
    <mesh name="b2_RL_thigh_visuals" file="unitree_b2/RL_thigh_visuals.obj"/>
    <mesh name="b2_RL_calf_collisions" file="unitree_b2/RL_calf_collisions.obj"/>
    <mesh name="b2_RL_calf_visuals" file="unitree_b2/RL_calf_visuals.obj"/>
    <mesh name="b2_RL_foot_collisions_Sphere" file="unitree_b2/RL_foot_collisions_Sphere.obj"/>
    <mesh name="b2_RL_foot_visuals" file="unitree_b2/RL_foot_visuals.obj"/>
    <mesh name="b2_RL_thigh_protect_collisions" file="unitree_b2/RL_thigh_protect_collisions.obj"/>
    <mesh name="b2_RL_thigh_protect_visuals" file="unitree_b2/RL_thigh_protect_visuals.obj"/>
    <mesh name="b2_RR_hip_collisions" file="unitree_b2/RR_hip_collisions.obj"/>
    <mesh name="b2_RR_hip_visuals" file="unitree_b2/RR_hip_visuals.obj"/>
    <mesh name="b2_RR_thigh_collisions" file="unitree_b2/RR_thigh_collisions.obj"/>
    <mesh name="b2_RR_thigh_visuals" file="unitree_b2/RR_thigh_visuals.obj"/>
    <mesh name="b2_RR_calf_collisions" file="unitree_b2/RR_calf_collisions.obj"/>
    <mesh name="b2_RR_calf_visuals" file="unitree_b2/RR_calf_visuals.obj"/>
    <mesh name="b2_RR_foot_collisions_Sphere" file="unitree_b2/RR_foot_collisions_Sphere.obj"/>
    <mesh name="b2_RR_foot_visuals" file="unitree_b2/RR_foot_visuals.obj"/>
    <mesh name="b2_RR_thigh_protect_collisions" file="unitree_b2/RR_thigh_protect_collisions.obj"/>
    <mesh name="b2_RR_thigh_protect_visuals" file="unitree_b2/RR_thigh_protect_visuals.obj"/>
    <mesh name="b2_f_dc_link_visuals" file="unitree_b2/f_dc_link_visuals.obj"/>
    <mesh name="b2_f_oc_link_visuals" file="unitree_b2/f_oc_link_visuals.obj"/>
    <mesh name="b2_lidar_link_visuals" file="unitree_b2/lidar_link_visuals.obj"/>
    <mesh name="b2_r_dc_link_visuals" file="unitree_b2/r_dc_link_visuals.obj"/>
    <mesh name="b2_r_oc_link_visuals" file="unitree_b2/r_oc_link_visuals.obj"/>
    <mesh name="b2_logo_left_link_visuals" file="unitree_b2/logo_left_link_visuals.obj"/>
    <mesh name="b2_logo_right_link_visuals" file="unitree_b2/logo_right_link_visuals.obj"/>
    <mesh name="z1_z1_Link00" file="unitree_z1/z1_Link00.stl"/>
    <mesh name="z1_z1_Link01" file="unitree_z1/z1_Link01.stl"/>
    <mesh name="z1_z1_Link02" file="unitree_z1/z1_Link02.stl"/>
    <mesh name="z1_z1_Link03" file="unitree_z1/z1_Link03.stl"/>
    <mesh name="z1_z1_Link04" file="unitree_z1/z1_Link04.stl"/>
    <mesh name="z1_z1_Link05" file="unitree_z1/z1_Link05.stl"/>
    <mesh name="z1_z1_Link06" file="unitree_z1/z1_Link06.stl"/>
    <mesh name="z1_z1_GripperStator" file="unitree_z1/z1_GripperStator.stl"/>
    <mesh name="z1_z1_GripperStator_col_1" file="unitree_z1/z1_GripperStator_col_1.stl"/>
    <mesh name="z1_z1_GripperStator_col_2" file="unitree_z1/z1_GripperStator_col_2.stl"/>
    <mesh name="z1_z1_GripperStator_col_3" file="unitree_z1/z1_GripperStator_col_3.stl"/>
    <mesh name="z1_z1_GripperStator_col_4" file="unitree_z1/z1_GripperStator_col_4.stl"/>
    <mesh name="z1_z1_GripperStator_col_5" file="unitree_z1/z1_GripperStator_col_5.stl"/>
    <mesh name="z1_z1_GripperStator_col_6" file="unitree_z1/z1_GripperStator_col_6.stl"/>
    <mesh name="z1_z1_GripperMover" file="unitree_z1/z1_GripperMover.stl"/>
    <mesh name="z1_z1_GripperMover_col_1" file="unitree_z1/z1_GripperMover_col_1.stl"/>
    <mesh name="z1_z1_GripperMover_col_2" file="unitree_z1/z1_GripperMover_col_2.stl"/>
    <mesh name="z1_z1_GripperMover_col_3" file="unitree_z1/z1_GripperMover_col_3.stl"/>
    <mesh name="z1_z1_GripperMover_col_4" file="unitree_z1/z1_GripperMover_col_4.stl"/>
    <mesh name="z1_z1_GripperMover_col_5" file="unitree_z1/z1_GripperMover_col_5.stl"/>
  </asset>

  <worldbody>
    <geom name="ground" size="0 0 1" type="plane" friction="2 0.05 0.01" material="matplane"/>
    <site pos="0.5 0 0" quat="0.707107 0 0.707107 0" size="0.005 0.5" type="cylinder" rgba="1 0 0 1"/>
    <site pos="0 0.5 0" quat="0.707107 0.707107 0 0" size="0.005 0.5" type="cylinder" rgba="0 1 0 1"/>
    <site pos="0 0 0.5" size="0.005 0.5" type="cylinder" rgba="0 0 1 1"/>
    <light pos="0 0 2" dir="0 0 -1" diffuse="0.4 0.4 0.4" specular="0.1 0.1 0.1"/>
    <light pos="0 0 4" dir="0 0 -1" type="directional" diffuse="0.8 0.8 0.8" specular="0.2 0.2 0.2"/>
    <body name="Target" mocap="true">
      <site pos="0.05 0 0" quat="0.707107 0 0.707107 0" size="0.002 0.05" group="4" type="cylinder" rgba="1 0 0 1"/>
      <site pos="0 0.05 0" quat="0.707107 0.707107 0 0" size="0.002 0.05" group="4" type="cylinder" rgba="0 1 0 1"/>
      <site pos="0 0 0.05" size="0.002 0.05" group="4" type="cylinder" rgba="0 0 1 1"/>
      <site name="Target" pos="0 0 0" size="0.01" group="1" rgba="1 0.5 1 0.5"/>
    </body>
    <body name="b2_base" childclass="b2_robot" pos="0 0 0.76">
      <joint name="b2_floating_base" type="free"/>
      <geom name="b2_head_collision" class="b2_collision" type="mesh" material="b2_collision_material" mesh="b2_b2_head_collisions"/>
      <geom name="b2_mainbody_collision" class="b2_collision" type="mesh" material="b2_collision_material" mesh="b2_b2_mainbody_collisions"/>
      <geom name="b2_base_link_visual" class="b2_visual" type="mesh" material="b2_default_material" mesh="b2_base_link_visuals"/>
      <site name="b2_base_site" pos="0 0 0"/>
      <camera name="b2_front_camera" pos="0 2 0.5" quat="0 0 0.707107 0.707107" mode="track" fovy="90"/>
      <camera name="b2_side_camera" pos="-2 0 0.5" quat="-0.5 -0.5 0.5 0.5" mode="track" fovy="90"/>
      <body name="b2_FL_hip" pos="0.3285 0.072 0">
        <inertial pos="-0.009305 -0.010228 0.000264" mass="2.256" diaginertia="0.0031671 0.0058614 0.0052608"/>
        <joint name="b2_FL_hip_joint" class="b2_motor" pos="0 0 0" axis="1 0 0" range="-0.87 0.87"/>
        <geom name="b2_FL_hip_collision" class="b2_collision" type="mesh" material="b2_collision_material" mesh="b2_FL_hip_collisions"/>
        <geom name="b2_FL_hip_visual" class="b2_visual" type="mesh" material="b2_default_material" mesh="b2_FL_hip_visuals"/>
        <body name="b2_FL_thigh" pos="0 0.11973 0" quat="0.707107 0 0 0.707107">
          <inertial pos="-0.004346 -0.035797 -0.044921" mass="3.591" diaginertia="0.061849 0.0559538 0.0116601"/>
          <joint name="b2_FL_thigh_joint" class="b2_motor" pos="0 0 0" axis="1 0 0" range="-0.94 4.69"/>
          <geom name="b2_FL_thigh_collision" class="b2_collision" quat="0.707107 0 0 -0.707107" type="mesh" material="b2_collision_material" mesh="b2_FL_thigh_collisions"/>
          <geom name="b2_FL_thigh_visual" class="b2_visual" quat="0.707107 0 0 -0.707107" type="mesh" material="b2_default_material" mesh="b2_FL_thigh_visuals"/>
          <body name="b2_FL_calf" pos="-8.7e-05 0 -0.35">
            <inertial pos="0.012422 0 -0.12499" mass="0.58094" diaginertia="0.0094888 0.0095945 0.0003011"/>
            <joint name="b2_FL_calf_joint" class="b2_motor" pos="0 0 0" axis="1 0 0" range="-2.82 -0.43"/>
            <geom name="b2_FL_calf_collision" class="b2_collision" pos="0 0 0" quat="0.707107 0 0 -0.707107" type="mesh" material="b2_collision_material" mesh="b2_FL_calf_collisions"/>
            <geom name="b2_FL_calf_visual" class="b2_visual" pos="0 0 0" quat="0.707107 0 0 -0.707107" type="mesh" material="b2_default_material" mesh="b2_FL_calf_visuals"/>
            <body name="b2_FL_foot" pos="8.7e-05 0 -0.35" quat="0.5 0.5 0.5 -0.5">
              <inertial pos="-0.006511 0 -0.010144" mass="0.098183" diaginertia="1e-05 1e-05 1e-05"/>
              <geom name="b2_FL_foot_collision" class="b2_collision" pos="0.0010595 0 -0.0006556" quat="0.707107 0 -0.707107 0" type="mesh" material="b2_collision_material" mesh="b2_FL_foot_collisions_Sphere"/>
              <geom name="b2_FL_foot_visual_0" class="b2_visual" pos="-0.35 0 0" quat="0.707107 0 -0.707107 0" type="mesh" material="b2_default_material" mesh="b2_FL_foot_visuals"/>
            </body>
          </body>
          <body name="b2_FL_thigh_protect" quat="0.707107 0 0 -0.707107">
            <inertial pos="-0.004346 -0.035797 -0.044921" mass="3.591" diaginertia="0.0624972 0.0587482 0.0107064"/>
            <geom name="b2_FL_thigh_protect_collision" class="b2_collision" type="mesh" material="b2_collision_material" mesh="b2_FL_thigh_protect_collisions"/>
            <geom name="b2_FL_thigh_protect_visual" class="b2_visual" type="mesh" material="b2_default_material" mesh="b2_FL_thigh_protect_visuals"/>
          </body>
        </body>
      </body>
      <body name="b2_FR_hip" pos="0.3285 -0.072 0">
        <inertial pos="-0.009305 0.010228 0.000264" mass="2.256" diaginertia="0.0031655 0.0058355 0.0052803"/>
        <joint name="b2_FR_hip_joint" class="b2_motor" pos="0 0 0" axis="1 0 0" range="-0.87 0.87"/>
        <geom name="b2_FR_hip_collision" class="b2_collision" type="mesh" material="b2_collision_material" mesh="b2_FR_hip_collisions"/>
        <geom name="b2_FR_hip_visual" class="b2_visual" type="mesh" material="b2_default_material" mesh="b2_FR_hip_visuals"/>
        <body name="b2_FR_thigh" pos="0 -0.11973 0" quat="0.707107 0 0 0.707107">
          <inertial pos="-0.004346 0.035797 -0.044921" mass="3.591" diaginertia="0.061849 0.0559535 0.0116603"/>
          <joint name="b2_FR_thigh_joint" class="b2_motor" pos="0 0 0" axis="1 0 0" range="-0.94 4.69"/>
          <geom name="b2_FR_thigh_collision" class="b2_collision" quat="0.707107 0 0 -0.707107" type="mesh" material="b2_collision_material" mesh="b2_FR_thigh_collisions"/>
          <geom name="b2_FR_thigh_visual" class="b2_visual" quat="0.707107 0 0 -0.707107" type="mesh" material="b2_default_material" mesh="b2_FR_thigh_visuals"/>
          <body name="b2_FR_calf" pos="8.7e-05 0 -0.35">
            <inertial pos="0.012422 0 -0.12499" mass="0.58094" diaginertia="0.0094888 0.0095945 0.0003011"/>
            <joint name="b2_FR_calf_joint" class="b2_motor" pos="0 0 0" axis="1 0 0" range="-2.82 -0.43"/>
            <geom name="b2_FR_calf_collision" class="b2_collision" pos="0 0 0" quat="0.707107 0 0 -0.707107" type="mesh" material="b2_collision_material" mesh="b2_FR_calf_collisions"/>
            <geom name="b2_FR_calf_visual" class="b2_visual" pos="0 0 0" quat="0.707107 0 0 -0.707107" type="mesh" material="b2_default_material" mesh="b2_FR_calf_visuals"/>
            <body name="b2_FR_foot" pos="0 0 -0.35" quat="0.5 0.5 0.5 -0.5">
              <inertial pos="-0.006511 0 -0.010144" mass="0.098183" diaginertia="1e-05 1e-05 1e-05"/>
              <geom name="b2_FR_foot_collision" class="b2_collision" pos="0.0010595 0 -0.0006556" quat="0.707107 0 -0.707107 0" type="mesh" material="b2_collision_material" mesh="b2_FR_foot_collisions_Sphere"/>
              <geom name="b2_FR_foot_visual_0" class="b2_visual" pos="-0.35 0 0" quat="0.707107 0 -0.707107 0" type="mesh" material="b2_default_material" mesh="b2_FR_foot_visuals"/>
            </body>
          </body>
          <body name="b2_FR_thigh_protect" quat="0.707107 0 0 -0.707107">
            <inertial pos="-0.004346 0.035797 -0.044921" mass="3.591" diaginertia="0.0624975 0.0587485 0.0107063"/>
            <geom name="b2_FR_thigh_protect_collision" class="b2_collision" type="mesh" material="b2_collision_material" mesh="b2_FR_thigh_protect_collisions"/>
            <geom name="b2_FR_thigh_protect_visual" class="b2_visual" type="mesh" material="b2_default_material" mesh="b2_FR_thigh_protect_visuals"/>
          </body>
        </body>
      </body>
      <body name="b2_RL_hip" pos="-0.3285 0.072 0">
        <inertial pos="0.009305 -0.010228 0.000264" mass="2.256" diaginertia="0.0031722 0.0058393 0.0052646"/>
        <joint name="b2_RL_hip_joint" class="b2_motor" pos="0 0 0" axis="1 0 0" range="-0.87 0.87"/>
        <geom name="b2_RL_hip_collision" class="b2_collision" type="mesh" material="b2_collision_material" mesh="b2_RL_hip_collisions"/>
        <geom name="b2_RL_hip_visual" class="b2_visual" type="mesh" material="b2_default_material" mesh="b2_RL_hip_visuals"/>
        <body name="b2_RL_thigh" pos="0 0.11973 0" quat="0.707107 0 0 0.707107">
          <inertial pos="-0.004346 -0.035797 -0.044921" mass="3.591" diaginertia="0.061849 0.0559538 0.0116601"/>
          <joint name="b2_RL_thigh_joint" class="b2_motor" pos="0 0 0" axis="1 0 0" range="-0.94 4.69"/>
          <geom name="b2_RL_thigh_collision" class="b2_collision" quat="0.707107 0 0 -0.707107" type="mesh" material="b2_collision_material" mesh="b2_RL_thigh_collisions"/>
          <geom name="b2_RL_thigh_visual" class="b2_visual" quat="0.707107 0 0 -0.707107" type="mesh" material="b2_default_material" mesh="b2_RL_thigh_visuals"/>
          <body name="b2_RL_calf" pos="-8.7e-05 0 -0.35">
            <inertial pos="0.012422 0 -0.12499" mass="0.58094" diaginertia="0.0094888 0.0095945 0.0003011"/>
            <joint name="b2_RL_calf_joint" class="b2_motor" pos="0 0 0" axis="1 0 0" range="-2.82 -0.43"/>
            <geom name="b2_RL_calf_collision" class="b2_collision" pos="0 0 0" quat="0.707107 0 0 -0.707107" type="mesh" material="b2_collision_material" mesh="b2_RL_calf_collisions"/>
            <geom name="b2_RL_calf_visual" class="b2_visual" pos="0 0 0" quat="0.707107 0 0 -0.707107" type="mesh" material="b2_default_material" mesh="b2_RL_calf_visuals"/>
            <body name="b2_RL_foot" pos="8.7e-05 0 -0.35" quat="0.5 0.5 0.5 -0.5">
              <inertial pos="-0.006511 0 -0.010144" mass="0.098183" diaginertia="1e-05 1e-05 1e-05"/>
              <geom name="b2_RL_foot_collision" class="b2_collision" pos="0.0010595 0 -0.0006556" quat="0.707107 0 -0.707107 0" type="mesh" material="b2_collision_material" mesh="b2_RL_foot_collisions_Sphere"/>
              <geom name="b2_RL_foot_visual_0" class="b2_visual" pos="-0.35 0 0" quat="0.707107 0 -0.707107 0" type="mesh" material="b2_default_material" mesh="b2_RL_foot_visuals"/>
            </body>
          </body>
          <body name="b2_RL_thigh_protect">
            <inertial pos="-0.004346 -0.035797 -0.044921" mass="3.591" diaginertia="0.0624972 0.0587482 0.0107064"/>
            <geom name="b2_RL_thigh_protect_collision" class="b2_collision" quat="0.707107 0 0 -0.707107" type="mesh" material="b2_collision_material" mesh="b2_RL_thigh_protect_collisions"/>
            <geom name="b2_RL_thigh_protect_visual" class="b2_visual" quat="0.707107 0 0 -0.707107" type="mesh" material="b2_default_material" mesh="b2_RL_thigh_protect_visuals"/>
          </body>
        </body>
      </body>
      <body name="b2_RR_hip" pos="-0.3285 -0.072 0">
        <inertial pos="0.009305 -0.010228 0.000264" mass="2.256" diaginertia="0.0035746 0.0058818 0.0056888"/>
        <joint name="b2_RR_hip_joint" class="b2_motor" pos="0 0 0" axis="1 0 0" range="-0.87 0.87"/>
        <geom name="b2_RR_hip_collision" class="b2_collision" type="mesh" material="b2_collision_material" mesh="b2_RR_hip_collisions"/>
        <geom name="b2_RR_hip_visual" class="b2_visual" type="mesh" material="b2_default_material" mesh="b2_RR_hip_visuals"/>
        <body name="b2_RR_thigh" pos="0 -0.11973 0" quat="0.707107 0 0 0.707107">
          <inertial pos="-0.004346 0.035797 -0.044921" mass="3.591" diaginertia="0.061849 0.0559535 0.0116603"/>
          <joint name="b2_RR_thigh_joint" class="b2_motor" pos="0 0 0" axis="1 0 0" range="-0.94 4.69"/>
          <geom name="b2_RR_thigh_collision" class="b2_collision" quat="0.707107 0 0 -0.707107" type="mesh" material="b2_collision_material" mesh="b2_RR_thigh_collisions"/>
          <geom name="b2_RR_thigh_visual" class="b2_visual" quat="0.707107 0 0 -0.707107" type="mesh" material="b2_default_material" mesh="b2_RR_thigh_visuals"/>
          <body name="b2_RR_calf" pos="8.7e-05 0 -0.35">
            <inertial pos="0.012422 0 -0.12499" mass="0.58094" diaginertia="0.0094888 0.0095945 0.0003011"/>
            <joint name="b2_RR_calf_joint" class="b2_motor" pos="0 0 0" axis="1 0 0" range="-2.82 -0.43"/>
            <geom name="b2_RR_calf_collision" class="b2_collision" pos="0 0 0" quat="0.707107 0 0 -0.707107" type="mesh" material="b2_collision_material" mesh="b2_RR_calf_collisions"/>
            <geom name="b2_RR_calf_visual" class="b2_visual" pos="0 0 0" quat="0.707107 0 0 -0.707107" type="mesh" material="b2_default_material" mesh="b2_RR_calf_visuals"/>
            <body name="b2_RR_foot" pos="-8.7e-05 0 -0.35" quat="0.5 0.5 0.5 -0.5">
              <inertial pos="-0.006511 0 -0.010144" mass="0.098183" diaginertia="1e-05 1e-05 1e-05"/>
              <geom name="b2_RR_foot_collision" class="b2_collision" pos="0.0010595 0 -0.0006556" quat="0.707107 0 -0.707107 0" type="mesh" material="b2_collision_material" mesh="b2_RR_foot_collisions_Sphere"/>
              <geom name="b2_RR_foot_visual_0" class="b2_visual" pos="-0.35 0 0" quat="0.707107 0 -0.707107 0" type="mesh" material="b2_default_material" mesh="b2_RR_foot_visuals"/>
            </body>
          </body>
          <body name="b2_RR_thigh_protect" quat="0.707107 0 0 -0.707107">
            <inertial pos="-0.004346 0.035797 -0.044921" mass="3.591" diaginertia="0.0624975 0.0587485 0.0107063"/>
            <geom name="b2_RR_thigh_protect_collision" class="b2_collision" type="mesh" material="b2_collision_material" mesh="b2_RR_thigh_protect_collisions"/>
            <geom name="b2_RR_thigh_protect_visual" class="b2_visual" type="mesh" material="b2_default_material" mesh="b2_RR_thigh_protect_visuals"/>
          </body>
        </body>
      </body>
      <body name="b2_f_dc_link" quat="0.707107 0 0.707107 0">
        <inertial pos="0 0 0" mass="1e-07" diaginertia="1e-05 1e-05 1e-05"/>
        <geom name="b2_f_dc_link_visual" class="b2_visual" pos="-0.001 0 0.0015" quat="0.707107 0 -0.707107 0" type="mesh" material="b2_default_material" mesh="b2_f_dc_link_visuals"/>
      </body>
      <body name="b2_f_oc_link" pos="0.003 0 0" quat="0.707107 0 0.707107 0">
        <inertial pos="0 0 0" mass="1e-07" diaginertia="1e-05 1e-05 1e-05"/>
        <geom name="b2_f_oc_link_visual" class="b2_visual" pos="0 0 0.001" quat="0.707107 0 -0.707107 0" type="mesh" material="b2_default_material" mesh="b2_f_oc_link_visuals"/>
      </body>
      <body name="b2_head_Link" quat="0.707107 0 0.707107 0">
        <inertial pos="0.33989 -0.000168 0.12029" mass="3.366" diaginertia="1e-05 1e-05 1e-05"/>
      </body>
      <body name="b2_imu_link" pos="0 -0.02341 0.04927" quat="0.707107 0 0.707107 0">
        <inertial pos="0 0 0" mass="1e-07" diaginertia="1e-05 1e-05 1e-05"/>
      </body>
      <body name="b2_lidar_link" quat="0.707107 0 0.707107 0">
        <inertial pos="0 0 0" mass="1e-07" diaginertia="1e-05 1e-05 1e-05"/>
        <geom name="b2_lidar_link_visual" class="b2_visual" pos="0 0 0" quat="0.707107 0 -0.707107 0" type="mesh" material="b2_default_material" mesh="b2_lidar_link_visuals"/>
      </body>
      <body name="b2_r_dc_link" quat="0.707107 0 0.707107 0">
        <inertial pos="0 0 0" mass="1e-07" diaginertia="1e-05 1e-05 1e-05"/>
        <geom name="b2_r_dc_link_visual" class="b2_visual" pos="-0.001 0 -0.001" quat="0.707107 0 -0.707107 0" type="mesh" material="b2_default_material" mesh="b2_r_dc_link_visuals"/>
      </body>
      <body name="b2_r_oc_link" pos="-0.003 0 0" quat="0.707107 0 0.707107 0">
        <inertial pos="0 0 0" mass="1e-07" diaginertia="1e-05 1e-05 1e-05"/>
        <geom name="b2_r_oc_link_visual" class="b2_visual" pos="0 0 -0.001" quat="0.707107 0 -0.707107 0" type="mesh" material="b2_default_material" mesh="b2_r_oc_link_visuals"/>
      </body>
      <body name="b2_tail_link" quat="0.707107 0 0.707107 0">
        <inertial pos="-0.37448 0.000488 0.006495" mass="0.777" diaginertia="1e-05 1e-05 1e-05"/>
      </body>
      <body name="b2_logo_left_link" pos="0 0.0015 0.0015" quat="0.707107 0 0.707107 0">
        <inertial pos="0 0 0" mass="1e-07" diaginertia="1e-05 1e-05 1e-05"/>
        <geom name="b2_logo_left_link_visual" class="b2_visual" pos="0 0 0" quat="0.707107 0 -0.707107 0" type="mesh" material="b2_default_material" mesh="b2_logo_left_link_visuals"/>
      </body>
      <body name="b2_logo_right_link" pos="0 -0.0015 0.0015" quat="0.707107 0 0.707107 0">
        <inertial pos="0 0 0" mass="1e-07" diaginertia="1e-05 1e-05 1e-05"/>
        <geom name="b2_logo_right_link_visual" class="b2_visual" pos="0 0 0" quat="0.707107 0 -0.707107 0" type="mesh" material="b2_default_material" mesh="b2_logo_right_link_visuals"/>
      </body>
      <body name="z1" childclass="z1_robot" pos="0 0 0.09">
        <inertial pos="-0.00334984 -0.00013615 0.0249584" quat="-0.00692194 0.682592 0.00133293 0.730766" mass="0.472475" diaginertia="0.000531375 0.000415207 0.000378658"/>
        <geom class="z1_visual" mesh="z1_z1_Link00"/>
        <geom class="z1_collision" size="0.0325 0.0255" pos="0 0 0.0255"/>
        <site name="z1_x" pos="0.25 0 0" quat="0.707107 0 0.707107 0" size="0.01 0.25" group="1" type="cylinder" rgba="1 0 0 1"/>
        <site name="z1_y" pos="0 0.25 0" quat="0.707107 0.707107 0 0" size="0.01 0.25" group="1" type="cylinder" rgba="0 1 0 1"/>
        <site name="z1_z" pos="0 0 0.25" size="0.01 0.25" group="1" type="cylinder" rgba="0 0 1 1"/>
        <body name="z1_link01" pos="0 0 0.0585">
          <inertial pos="2.47e-06 -0.00025198 0.0231717" quat="0.708578 0.705633 0.000281462 -0.000355927" mass="0.673326" diaginertia="0.00128328 0.000839362 0.000719308"/>
          <joint name="z1_joint1" pos="0 0 0" axis="0 0 1" range="-2.61799 2.61799"/>
          <geom class="z1_visual" mesh="z1_z1_Link01"/>
          <body name="z1_link02" pos="0 0 0.045">
            <inertial pos="-0.110126 0.00240029 0.00158266" quat="0.00748058 0.707092 -0.0114473 0.70699" mass="1.19132" diaginertia="0.0246612 0.0243113 0.00100468"/>
            <joint name="z1_joint2" pos="0 0 0" axis="0 1 0" range="0 2.96706" damping="2"/>
            <geom class="z1_visual" mesh="z1_z1_Link02"/>
            <geom class="z1_collision" size="0.0325 0.051" quat="0.707107 0.707107 0 0"/>
            <geom class="z1_collision" size="0.0225 0.1175" pos="-0.1625 0 0" quat="0.707107 0 0.707107 0"/>
            <geom class="z1_collision" size="0.0325 0.0255" pos="-0.35 0 0" quat="0.707107 0.707107 0 0"/>
            <body name="z1_link03" pos="-0.35 0 0">
              <inertial pos="0.106092 -0.00541815 0.0347638" quat="0.540557 0.443575 0.426319 0.573839" mass="0.839409" diaginertia="0.00954365 0.00938711 0.000558432"/>
              <joint name="z1_joint3" pos="0 0 0" axis="0 1 0" range="-2.87979 0"/>
              <geom class="z1_visual" mesh="z1_z1_Link03"/>
              <geom class="z1_collision" size="0.02 0.058" pos="0.128 0 0.055" quat="0.707107 0 0.707107 0"/>
              <geom class="z1_collision" size="0.0325 0.0295" pos="0.2205 0 0.055" quat="0.5 -0.5 0.5 0.5"/>
              <body name="z1_link04" pos="0.218 0 0.057">
                <inertial pos="0.0436668 0.00364738 -0.00170192" quat="0.0390835 0.726445 -0.0526787 0.684087" mass="0.564046" diaginertia="0.000981656 0.00094053 0.000302655"/>
                <joint name="z1_joint4" pos="0 0 0" axis="0 1 0" range="-1.51844 1.51844"/>
                <geom class="z1_visual" mesh="z1_z1_Link04"/>
                <geom class="z1_collision" size="0.0325 0.0335" pos="0.072 0 0"/>
                <body name="z1_link05" pos="0.07 0 0">
                  <inertial pos="0.0312153 0 0.00646316" quat="0.462205 0.535209 0.53785 0.45895" mass="0.389385" diaginertia="0.000558961 0.000547317 0.000167332"/>
                  <joint name="z1_joint5" pos="0 0 0" axis="0 0 1" range="-1.3439 1.3439"/>
                  <geom class="z1_visual" mesh="z1_z1_Link05"/>
                  <body name="z1_link06" pos="0.0492 0 0">
                    <inertial pos="0.0241569 -0.00017355 -0.00143876" quat="0.998779 0.0457735 -0.00663717 0.0173548" mass="0.288758" diaginertia="0.00018333 0.000147464 0.000146786"/>
                    <joint name="z1_joint6" pos="0 0 0" axis="1 0 0" range="-2.79253 2.79253"/>
                    <geom class="z1_visual" mesh="z1_z1_Link06"/>
                    <geom class="z1_collision" size="0.0325 0.0255" pos="0.0255 0 0" quat="0.707107 0 0.707107 0"/>
                    <geom class="z1_visual" pos="0.051 0 0" quat="1 0 0 0" mesh="z1_z1_GripperStator"/>
                    <geom class="z1_gripper_stator_collision" pos="0.051 0 0" quat="1 0 0 0" mesh="z1_z1_GripperStator_col_1"/>
                    <geom class="z1_gripper_stator_collision" pos="0.051 0 0" quat="1 0 0 0" mesh="z1_z1_GripperStator_col_2"/>
                    <geom class="z1_gripper_stator_collision" pos="0.051 0 0" quat="1 0 0 0" mesh="z1_z1_GripperStator_col_3"/>
                    <geom class="z1_gripper_stator_collision" pos="0.051 0 0" quat="1 0 0 0" mesh="z1_z1_GripperStator_col_4"/>
                    <geom class="z1_gripper_stator_collision" pos="0.051 0 0" quat="1 0 0 0" mesh="z1_z1_GripperStator_col_5"/>
                    <geom class="z1_gripper_stator_collision" pos="0.051 0 0" quat="1 0 0 0" mesh="z1_z1_GripperStator_col_6"/>
                    <geom class="z1_gripper_stator_pad_collision_1" pos="0.186 -0.015 -0.0125"/>
                    <geom class="z1_gripper_stator_pad_collision_2" pos="0.186 0.015 -0.0125"/>
                    <body name="z1_gripperMover" pos="0.1 0 0">
                      <inertial pos="0.0132063 0.00476708 0.00380534" quat="0.0631093 0.669067 -0.0615783 0.737953" mass="0.276213" diaginertia="0.000359044 0.000270888 0.000172378"/>
                      <joint name="z1_jointGripper" pos="0 0 0" axis="0 1 0" range="-1.51844 0"/>
                      <geom class="z1_visual" mesh="z1_z1_GripperMover"/>
                      <geom class="z1_gripper_mover_collision" mesh="z1_z1_GripperMover_col_1"/>
                      <geom class="z1_gripper_mover_collision" mesh="z1_z1_GripperMover_col_2"/>
                      <geom class="z1_gripper_mover_collision" mesh="z1_z1_GripperMover_col_3"/>
                      <geom class="z1_gripper_mover_collision" mesh="z1_z1_GripperMover_col_4"/>
                      <geom class="z1_gripper_mover_collision" mesh="z1_z1_GripperMover_col_5"/>
                      <geom class="z1_gripper_mover_pad_collision_1" pos="0.086 -0.015 -0.0055"/>
                      <geom class="z1_gripper_mover_pad_collision_2" pos="0.086 0.015 -0.0055"/>
                    </body>
                    <body name="z1_flange" quat="0.707105 0 0.707108 0">
                      <site pos="0.0625 0 0" quat="0.707107 0 0.707107 0" size="0.005 0.0625" group="3" type="cylinder" rgba="1 0 0 1"/>
                      <site pos="0 0.0625 0" quat="0.707107 0.707107 0 0" size="0.005 0.0625" group="3" type="cylinder" rgba="0 1 0 1"/>
                      <site pos="0 0 0.0625" size="0.005 0.0625" group="3" type="cylinder" rgba="0 0 1 1"/>
                      <site name="z1_flange" pos="0 0 0"/>
                      <body name="z1_hand">
                        <body name="z1_TCP" pos="0.0085 0 0.2">
                          <site pos="0.0625 0 0" quat="0.707107 0 0.707107 0" size="0.005 0.0625" group="4" type="cylinder" rgba="1 0 0 1"/>
                          <site pos="0 0.0625 0" quat="0.707107 0.707107 0 0" size="0.005 0.0625" group="4" type="cylinder" rgba="0 1 0 1"/>
                          <site pos="0 0 0.0625" size="0.005 0.0625" group="4" type="cylinder" rgba="0 0 1 1"/>
                          <site name="z1_TCP" pos="0 0 0" size="0.008" group="4"/>
                        </body>
                      </body>
                    </body>
                  </body>
                </body>
              </body>
            </body>
          </body>
        </body>
      </body>
    </body>
  </worldbody>

  <contact>
    <exclude body1="b2_base" body2="b2_FL_hip"/>
    <exclude body1="b2_base" body2="b2_FR_hip"/>
    <exclude body1="b2_base" body2="b2_RL_hip"/>
    <exclude body1="b2_base" body2="b2_RR_hip"/>
    <exclude body1="b2_FL_hip" body2="b2_FL_thigh"/>
    <exclude body1="b2_FL_thigh" body2="b2_FL_calf"/>
    <exclude body1="b2_FL_thigh" body2="b2_FL_thigh_protect"/>
    <exclude body1="b2_FL_calf" body2="b2_FL_foot"/>
    <exclude body1="b2_FR_hip" body2="b2_FR_thigh"/>
    <exclude body1="b2_FR_thigh" body2="b2_FR_calf"/>
    <exclude body1="b2_FR_thigh" body2="b2_FR_thigh_protect"/>
    <exclude body1="b2_FR_calf" body2="b2_FR_foot"/>
    <exclude body1="b2_RL_hip" body2="b2_RL_thigh"/>
    <exclude body1="b2_RL_thigh" body2="b2_RL_calf"/>
    <exclude body1="b2_RL_thigh" body2="b2_RL_thigh_protect"/>
    <exclude body1="b2_RL_calf" body2="b2_RL_foot"/>
    <exclude body1="b2_RR_hip" body2="b2_RR_thigh"/>
    <exclude body1="b2_RR_thigh" body2="b2_RR_calf"/>
    <exclude body1="b2_RR_thigh" body2="b2_RR_thigh_protect"/>
    <exclude body1="b2_RR_calf" body2="b2_RR_foot"/>
  </contact>

  <actuator>
    <general name="b2_pos_FL_hip_joint" joint="b2_FL_hip_joint" ctrlrange="-0.87 0.87" gainprm="4000" biasprm="0 -4000 -200"/>
    <general name="b2_pos_FL_thigh_joint" joint="b2_FL_thigh_joint" ctrlrange="-0.94 4.69" gainprm="4000" biasprm="0 -4000 -200"/>
    <general name="b2_pos_FL_calf_joint" joint="b2_FL_calf_joint" ctrlrange="-2.82 -0.43" gainprm="4000" biasprm="0 -4000 -200"/>
    <general name="b2_pos_FR_hip_joint" joint="b2_FR_hip_joint" ctrlrange="-0.87 0.87" gainprm="4000" biasprm="0 -4000 -200"/>
    <general name="b2_pos_FR_thigh_joint" joint="b2_FR_thigh_joint" ctrlrange="-0.94 4.69" gainprm="4000" biasprm="0 -4000 -200"/>
    <general name="b2_pos_FR_calf_joint" joint="b2_FR_calf_joint" ctrlrange="-2.82 -0.43" gainprm="4000" biasprm="0 -4000 -200"/>
    <general name="b2_pos_RL_hip_joint" joint="b2_RL_hip_joint" ctrlrange="-0.87 0.87" gainprm="4000" biasprm="0 -4000 -200"/>
    <general name="b2_pos_RL_thigh_joint" joint="b2_RL_thigh_joint" ctrlrange="-0.94 4.69" gainprm="4000" biasprm="0 -4000 -200"/>
    <general name="b2_pos_RL_calf_joint" joint="b2_RL_calf_joint" ctrlrange="-2.82 -0.43" gainprm="4000" biasprm="0 -4000 -200"/>
    <general name="b2_pos_RR_hip_joint" joint="b2_RR_hip_joint" ctrlrange="-0.87 0.87" gainprm="4000" biasprm="0 -4000 -200"/>
    <general name="b2_pos_RR_thigh_joint" joint="b2_RR_thigh_joint" ctrlrange="-0.94 4.69" gainprm="4000" biasprm="0 -4000 -200"/>
    <general name="b2_pos_RR_calf_joint" joint="b2_RR_calf_joint" ctrlrange="-2.82 -0.43" gainprm="4000" biasprm="0 -4000 -200"/>
    <general name="z1_actuator1" class="z1_robot" joint="z1_joint1" ctrlrange="-2.61799 2.61799"/>
    <general name="z1_actuator2" class="z1_robot" joint="z1_joint2" ctrlrange="0 2.96706"/>
    <general name="z1_actuator3" class="z1_robot" joint="z1_joint3" ctrlrange="-2.87979 0"/>
    <general name="z1_actuator4" class="z1_robot" joint="z1_joint4" ctrlrange="-1.51844 1.51844"/>
    <general name="z1_actuator5" class="z1_robot" joint="z1_joint5" ctrlrange="-1.3439 1.3439"/>
    <general name="z1_actuator6" class="z1_robot" joint="z1_joint6" ctrlrange="-2.79253 2.79253"/>
    <general name="z1_gripper" class="z1_robot" joint="z1_jointGripper" ctrlrange="-1.51844 0" gainprm="100" biasprm="0 -100 -20"/>
  </actuator>

  <sensor>
    <framepos objtype="site" objname="b2_base_site" name="b2_base_site_pos"/>
    <framequat objtype="site" objname="b2_base_site" name="b2_base_site_quat"/>
    <framelinvel objtype="site" objname="b2_base_site" name="b2_base_site_linvel"/>
    <frameangvel objtype="site" objname="b2_base_site" name="b2_base_site_angvel"/>
    <velocimeter site="b2_base_site" name="b2_base_site_vel"/>
  </sensor>

  <keyframe>
    <key name="b2_home" qpos="0 0 0.81 1 0 0 0 0.0522 0.27045 -0.43 -0.133625 -0.06735 -0.447855 0.087 0.240057 -0.709667 0.0261 0.4675 -0.429406 0 0 0 0 0 0 0" ctrl="0.0522 0.27045 -0.43 -0.133625 -0.06735 -0.447855 0.087 0.240057 -0.709667 0.0261 0.4675 -0.429406 0 0.785 -0.261 -0.523 0 0 0"/>
  </keyframe>
</mujoco>
