<?xml version="1.0" ?>
<!-- =================================================================================== -->
<!-- |    This document was autogenerated by xacro from hc20.xacro                     | -->
<!-- |    EDITING THIS FILE BY HAND IS NOT RECOMMENDED                                 | -->
<!-- =================================================================================== -->
<robot name="motoman_hc20">
  <!-- link list -->
  <link name="base_link">
    <visual>
      <geometry>
        <mesh filename="package://motoman_hc20_support/meshes/hc20/visual/base_link.dae"/>
      </geometry>
      <material name="">
        <color rgba="0.99 0.99 0.99 1"/>
      </material>
    </visual>
    <collision>
      <geometry>
        <mesh filename="package://motoman_hc20_support/meshes/hc20/collision/base_link.stl"/>
      </geometry>
    </collision>
  </link>
  <link name="link_1_s">
    <visual>
      <geometry>
        <mesh filename="package://motoman_hc20_support/meshes/hc20/visual/link_1_s.dae"/>
      </geometry>
      <material name="">
        <color rgba="0.99 0.99 0.99 1"/>
      </material>
    </visual>
    <collision>
      <geometry>
        <mesh filename="package://motoman_hc20_support/meshes/hc20/collision/link_1_s.stl"/>
      </geometry>
    </collision>
  </link>
  <link name="link_2_l">
    <visual>
      <geometry>
        <mesh filename="package://motoman_hc20_support/meshes/hc20/visual/link_2_l.dae"/>
      </geometry>
      <material name="">
        <color rgba="0.99 0.99 0.99 1"/>
      </material>
    </visual>
    <collision>
      <geometry>
        <mesh filename="package://motoman_hc20_support/meshes/hc20/collision/link_2_l.stl"/>
      </geometry>
    </collision>
  </link>
  <link name="link_3_u">
    <visual>
      <geometry>
        <mesh filename="package://motoman_hc20_support/meshes/hc20/visual/link_3_u.dae"/>
      </geometry>
      <material name="">
        <color rgba="0.99 0.99 0.99 1"/>
      </material>
    </visual>
    <collision>
      <geometry>
        <mesh filename="package://motoman_hc20_support/meshes/hc20/collision/link_3_u.stl"/>
      </geometry>
    </collision>
  </link>
  <link name="link_4_r">
    <visual>
      <geometry>
        <mesh filename="package://motoman_hc20_support/meshes/hc20/visual/link_4_r.dae"/>
      </geometry>
      <material name="">
        <color rgba="0.99 0.99 0.99 1"/>
      </material>
    </visual>
    <collision>
      <geometry>
        <mesh filename="package://motoman_hc20_support/meshes/hc20/collision/link_4_r.stl"/>
      </geometry>
    </collision>
  </link>
  <link name="link_5_b">
    <visual>
      <geometry>
        <mesh filename="package://motoman_hc20_support/meshes/hc20/visual/link_5_b.dae"/>
      </geometry>
      <material name="">
        <color rgba="0.99 0.99 0.99 1"/>
      </material>
    </visual>
    <collision>
      <geometry>
        <mesh filename="package://motoman_hc20_support/meshes/hc20/collision/link_5_b.stl"/>
      </geometry>
    </collision>
  </link>
  <link name="link_6_t">
    <visual>
      <geometry>
        <mesh filename="package://motoman_hc20_support/meshes/hc20/visual/link_6_t.dae"/>
      </geometry>
      <material name="">
        <color rgba="0.99 0.99 0.99 1"/>
      </material>
    </visual>
    <collision>
      <geometry>
        <mesh filename="package://motoman_hc20_support/meshes/hc20/collision/link_6_t.stl"/>
      </geometry>
    </collision>
  </link>
  <!-- end of link list -->
  <!-- joint list -->
  <joint name="joint_1_s" type="revolute">
    <parent link="base_link"/>
    <child link="link_1_s"/>
    <origin rpy="0 0 0" xyz="0 0 0.380"/>
    <axis xyz="0 0 1"/>
    <limit effort="917.28" lower="-3.141592653589793" upper="3.141592653589793" velocity="1.3962634015954636"/>
  </joint>
  <joint name="joint_2_l" type="revolute">
    <parent link="link_1_s"/>
    <child link="link_2_l"/>
    <origin rpy="0 0 0" xyz="0 0 0"/>
    <axis xyz="0 1 0"/>
    <limit effort="1223.04" lower="-3.141592653589793" upper="3.141592653589793" velocity="1.3962634015954636"/>
  </joint>
  <joint name="joint_3_u" type="revolute">
    <parent link="link_2_l"/>
    <child link="link_3_u"/>
    <origin rpy="0 0 0" xyz="0 0 0.820"/>
    <axis xyz="0 -1 0"/>
    <limit effort="642.88" lower="-1.1693705988362009" upper="4.310963252425994" velocity="2.0943951023931953"/>
  </joint>
  <joint name="joint_4_r" type="revolute">
    <parent link="link_3_u"/>
    <child link="link_4_r"/>
    <origin rpy="0 0 0" xyz="0.880 0 0"/>
    <axis xyz="-1 0 0"/>
    <limit effort="368.48" lower="-3.6651914291880923" upper="3.6651914291880923" velocity="2.2689280275926285"/>
  </joint>
  <joint name="joint_5_b" type="revolute">
    <parent link="link_4_r"/>
    <child link="link_5_b"/>
    <origin rpy="0 0 0" xyz="0 0 0"/>
    <axis xyz="0 -1 0"/>
    <limit effort="141.12" lower="-3.141592653589793" upper="3.141592653589793" velocity="3.141592653589793"/>
  </joint>
  <joint name="joint_6_t" type="revolute">
    <parent link="link_5_b"/>
    <child link="link_6_t"/>
    <origin rpy="0 0 0" xyz="0 0 0"/>
    <axis xyz="-1 0 0"/>
    <limit effort="141.12" lower="-3.6651914291880923" upper="3.6651914291880923" velocity="3.141592653589793"/>
  </joint>
  <!-- end of joint list -->
  <!-- ROS-Industrial 'flange' frame: attachment point for EEF models -->
  <link name="flange"/>
  <joint name="joint_6_t-flange" type="fixed">
    <origin rpy="0 0 0" xyz="0.200 0 0"/>
    <parent link="link_6_t"/>
    <child link="flange"/>
  </joint>
  <!-- ROS-Industrial 'tool0' frame: all-zeros tool frame -->
  <link name="tool0"/>
  <joint name="flange-tool0" type="fixed">
    <origin rpy="3.141592653589793 -1.5707963267948966 0" xyz="0 0 0"/>
    <parent link="flange"/>
    <child link="tool0"/>
  </joint>
  <!-- ROS base_link to Robot Manufacturer World Coordinates transform -->
  <link name="base"/>
  <joint name="base_link-base" type="fixed">
    <origin rpy="0 0 0" xyz="0 0 0.380"/>
    <parent link="base_link"/>
    <child link="base"/>
  </joint>
</robot>
